Internal Server Error: /dashboard/
Traceback (most recent call last):
  File "/mnt/c/Users/jreii/Desktop/IPTVGestão/.venv/lib/python3.10/site-packages/django/db/models/sql/query.py", line 1409, in build_filter
    join_info = self.setup_joins(
  File "/mnt/c/Users/jreii/Desktop/IPTVGestão/.venv/lib/python3.10/site-packages/django/db/models/sql/query.py", line 1780, in setup_joins
    path, final_field, targets, rest = self.names_to_path(
  File "/mnt/c/Users/jreii/Desktop/IPTVGestão/.venv/lib/python3.10/site-packages/django/db/models/sql/query.py", line 1705, in names_to_path
    raise MultiJoin(pos + 1, names_with_path)
django.db.models.sql.datastructures.MultiJoin: (1, [('mensalidade', [PathInfo(from_opts=<Options for Cliente>, to_opts=<Options for Mensalidade>, target_fields=(<django.db.models.fields.BigAutoField: id>,), join_field=<ManyToOneRel: cadastros.mensalidade>, m2m=True, direct=False, filtered_relation=None)])])

During handling of the above exception, another exception occurred:

Traceback (most recent call last):
  File "/mnt/c/Users/jreii/Desktop/IPTVGestão/.venv/lib/python3.10/site-packages/django/core/handlers/exception.py", line 55, in inner
    response = get_response(request)
  File "/mnt/c/Users/jreii/Desktop/IPTVGestão/.venv/lib/python3.10/site-packages/django/core/handlers/base.py", line 197, in _get_response
    response = wrapped_callback(request, *callback_args, **callback_kwargs)
  File "/mnt/c/Users/jreii/Desktop/IPTVGestão/.venv/lib/python3.10/site-packages/django/views/generic/base.py", line 104, in view
    return self.dispatch(request, *args, **kwargs)
  File "/mnt/c/Users/jreii/Desktop/IPTVGestão/.venv/lib/python3.10/site-packages/django/contrib/auth/mixins.py", line 73, in dispatch
    return super().dispatch(request, *args, **kwargs)
  File "/mnt/c/Users/jreii/Desktop/IPTVGestão/.venv/lib/python3.10/site-packages/django/views/generic/base.py", line 143, in dispatch
    return handler(request, *args, **kwargs)
  File "/mnt/c/Users/jreii/Desktop/IPTVGestão/.venv/lib/python3.10/site-packages/django/views/generic/list.py", line 154, in get
    self.object_list = self.get_queryset()
  File "/mnt/c/Users/jreii/Desktop/IPTVGestão/cadastros/views.py", line 84, in get_queryset
    Cliente.objects.filter(cancelado=False).filter(usuario=self.request.user,).exclude(mensalidade__cancelado=True, mensalidade__dt_cancelamento=True, mensalidade__dt_pagamento=True, mensalidade__pgto=True, ).order_by("mensalidade__dt_vencimento").distinct())
  File "/mnt/c/Users/jreii/Desktop/IPTVGestão/.venv/lib/python3.10/site-packages/django/db/models/query.py", line 1444, in exclude
    return self._filter_or_exclude(True, args, kwargs)
  File "/mnt/c/Users/jreii/Desktop/IPTVGestão/.venv/lib/python3.10/site-packages/django/db/models/query.py", line 1454, in _filter_or_exclude
    clone._filter_or_exclude_inplace(negate, args, kwargs)
  File "/mnt/c/Users/jreii/Desktop/IPTVGestão/.venv/lib/python3.10/site-packages/django/db/models/query.py", line 1459, in _filter_or_exclude_inplace
    self._query.add_q(~Q(*args, **kwargs))
  File "/mnt/c/Users/jreii/Desktop/IPTVGestão/.venv/lib/python3.10/site-packages/django/db/models/sql/query.py", line 1502, in add_q
    clause, _ = self._add_q(q_object, self.used_aliases)
  File "/mnt/c/Users/jreii/Desktop/IPTVGestão/.venv/lib/python3.10/site-packages/django/db/models/sql/query.py", line 1533, in _add_q
    child_clause, needed_inner = self.build_filter(
  File "/mnt/c/Users/jreii/Desktop/IPTVGestão/.venv/lib/python3.10/site-packages/django/db/models/sql/query.py", line 1427, in build_filter
    return self.split_exclude(filter_expr, can_reuse, e.names_with_path)
  File "/mnt/c/Users/jreii/Desktop/IPTVGestão/.venv/lib/python3.10/site-packages/django/db/models/sql/query.py", line 1981, in split_exclude
    query.add_filter(filter_lhs, filter_rhs)
  File "/mnt/c/Users/jreii/Desktop/IPTVGestão/.venv/lib/python3.10/site-packages/django/db/models/sql/query.py", line 1486, in add_filter
    self.add_q(Q((filter_lhs, filter_rhs)))
  File "/mnt/c/Users/jreii/Desktop/IPTVGestão/.venv/lib/python3.10/site-packages/django/db/models/sql/query.py", line 1502, in add_q
    clause, _ = self._add_q(q_object, self.used_aliases)
  File "/mnt/c/Users/jreii/Desktop/IPTVGestão/.venv/lib/python3.10/site-packages/django/db/models/sql/query.py", line 1533, in _add_q
    child_clause, needed_inner = self.build_filter(
  File "/mnt/c/Users/jreii/Desktop/IPTVGestão/.venv/lib/python3.10/site-packages/django/db/models/sql/query.py", line 1448, in build_filter
    condition = self.build_lookup(lookups, col, value)
  File "/mnt/c/Users/jreii/Desktop/IPTVGestão/.venv/lib/python3.10/site-packages/django/db/models/sql/query.py", line 1275, in build_lookup
    lookup = lookup_class(lhs, rhs)
  File "/mnt/c/Users/jreii/Desktop/IPTVGestão/.venv/lib/python3.10/site-packages/django/db/models/lookups.py", line 27, in __init__
    self.rhs = self.get_prep_lookup()
  File "/mnt/c/Users/jreii/Desktop/IPTVGestão/.venv/lib/python3.10/site-packages/django/db/models/lookups.py", line 341, in get_prep_lookup
    return super().get_prep_lookup()
  File "/mnt/c/Users/jreii/Desktop/IPTVGestão/.venv/lib/python3.10/site-packages/django/db/models/lookups.py", line 85, in get_prep_lookup
    return self.lhs.output_field.get_prep_value(self.rhs)
  File "/mnt/c/Users/jreii/Desktop/IPTVGestão/.venv/lib/python3.10/site-packages/django/db/models/fields/__init__.py", line 1464, in get_prep_value
    return self.to_python(value)
  File "/mnt/c/Users/jreii/Desktop/IPTVGestão/.venv/lib/python3.10/site-packages/django/db/models/fields/__init__.py", line 1420, in to_python
    parsed = parse_date(value)
  File "/mnt/c/Users/jreii/Desktop/IPTVGestão/.venv/lib/python3.10/site-packages/django/utils/dateparse.py", line 74, in parse_date
    return datetime.date.fromisoformat(value)
TypeError: fromisoformat: argument must be str
Internal Server Error: /dashboard/
Traceback (most recent call last):
  File "/mnt/c/Users/jreii/Desktop/IPTVGestão/.venv/lib/python3.10/site-packages/django/db/models/sql/query.py", line 1409, in build_filter
    join_info = self.setup_joins(
  File "/mnt/c/Users/jreii/Desktop/IPTVGestão/.venv/lib/python3.10/site-packages/django/db/models/sql/query.py", line 1780, in setup_joins
    path, final_field, targets, rest = self.names_to_path(
  File "/mnt/c/Users/jreii/Desktop/IPTVGestão/.venv/lib/python3.10/site-packages/django/db/models/sql/query.py", line 1705, in names_to_path
    raise MultiJoin(pos + 1, names_with_path)
django.db.models.sql.datastructures.MultiJoin: (1, [('mensalidade', [PathInfo(from_opts=<Options for Cliente>, to_opts=<Options for Mensalidade>, target_fields=(<django.db.models.fields.BigAutoField: id>,), join_field=<ManyToOneRel: cadastros.mensalidade>, m2m=True, direct=False, filtered_relation=None)])])

During handling of the above exception, another exception occurred:

Traceback (most recent call last):
  File "/mnt/c/Users/jreii/Desktop/IPTVGestão/.venv/lib/python3.10/site-packages/django/core/handlers/exception.py", line 55, in inner
    response = get_response(request)
  File "/mnt/c/Users/jreii/Desktop/IPTVGestão/.venv/lib/python3.10/site-packages/django/core/handlers/base.py", line 197, in _get_response
    response = wrapped_callback(request, *callback_args, **callback_kwargs)
  File "/mnt/c/Users/jreii/Desktop/IPTVGestão/.venv/lib/python3.10/site-packages/django/views/generic/base.py", line 104, in view
    return self.dispatch(request, *args, **kwargs)
  File "/mnt/c/Users/jreii/Desktop/IPTVGestão/.venv/lib/python3.10/site-packages/django/contrib/auth/mixins.py", line 73, in dispatch
    return super().dispatch(request, *args, **kwargs)
  File "/mnt/c/Users/jreii/Desktop/IPTVGestão/.venv/lib/python3.10/site-packages/django/views/generic/base.py", line 143, in dispatch
    return handler(request, *args, **kwargs)
  File "/mnt/c/Users/jreii/Desktop/IPTVGestão/.venv/lib/python3.10/site-packages/django/views/generic/list.py", line 154, in get
    self.object_list = self.get_queryset()
  File "/mnt/c/Users/jreii/Desktop/IPTVGestão/cadastros/views.py", line 84, in get_queryset
    Cliente.objects.filter(cancelado=False).filter(usuario=self.request.user,).exclude(mensalidade__cancelado=True, mensalidade__dt_cancelamento=True, mensalidade__dt_pagamento=True, mensalidade__pgto=True, ).order_by("mensalidade__dt_vencimento").distinct())
  File "/mnt/c/Users/jreii/Desktop/IPTVGestão/.venv/lib/python3.10/site-packages/django/db/models/query.py", line 1444, in exclude
    return self._filter_or_exclude(True, args, kwargs)
  File "/mnt/c/Users/jreii/Desktop/IPTVGestão/.venv/lib/python3.10/site-packages/django/db/models/query.py", line 1454, in _filter_or_exclude
    clone._filter_or_exclude_inplace(negate, args, kwargs)
  File "/mnt/c/Users/jreii/Desktop/IPTVGestão/.venv/lib/python3.10/site-packages/django/db/models/query.py", line 1459, in _filter_or_exclude_inplace
    self._query.add_q(~Q(*args, **kwargs))
  File "/mnt/c/Users/jreii/Desktop/IPTVGestão/.venv/lib/python3.10/site-packages/django/db/models/sql/query.py", line 1502, in add_q
    clause, _ = self._add_q(q_object, self.used_aliases)
  File "/mnt/c/Users/jreii/Desktop/IPTVGestão/.venv/lib/python3.10/site-packages/django/db/models/sql/query.py", line 1533, in _add_q
    child_clause, needed_inner = self.build_filter(
  File "/mnt/c/Users/jreii/Desktop/IPTVGestão/.venv/lib/python3.10/site-packages/django/db/models/sql/query.py", line 1427, in build_filter
    return self.split_exclude(filter_expr, can_reuse, e.names_with_path)
  File "/mnt/c/Users/jreii/Desktop/IPTVGestão/.venv/lib/python3.10/site-packages/django/db/models/sql/query.py", line 1981, in split_exclude
    query.add_filter(filter_lhs, filter_rhs)
  File "/mnt/c/Users/jreii/Desktop/IPTVGestão/.venv/lib/python3.10/site-packages/django/db/models/sql/query.py", line 1486, in add_filter
    self.add_q(Q((filter_lhs, filter_rhs)))
  File "/mnt/c/Users/jreii/Desktop/IPTVGestão/.venv/lib/python3.10/site-packages/django/db/models/sql/query.py", line 1502, in add_q
    clause, _ = self._add_q(q_object, self.used_aliases)
  File "/mnt/c/Users/jreii/Desktop/IPTVGestão/.venv/lib/python3.10/site-packages/django/db/models/sql/query.py", line 1533, in _add_q
    child_clause, needed_inner = self.build_filter(
  File "/mnt/c/Users/jreii/Desktop/IPTVGestão/.venv/lib/python3.10/site-packages/django/db/models/sql/query.py", line 1448, in build_filter
    condition = self.build_lookup(lookups, col, value)
  File "/mnt/c/Users/jreii/Desktop/IPTVGestão/.venv/lib/python3.10/site-packages/django/db/models/sql/query.py", line 1275, in build_lookup
    lookup = lookup_class(lhs, rhs)
  File "/mnt/c/Users/jreii/Desktop/IPTVGestão/.venv/lib/python3.10/site-packages/django/db/models/lookups.py", line 27, in __init__
    self.rhs = self.get_prep_lookup()
  File "/mnt/c/Users/jreii/Desktop/IPTVGestão/.venv/lib/python3.10/site-packages/django/db/models/lookups.py", line 341, in get_prep_lookup
    return super().get_prep_lookup()
  File "/mnt/c/Users/jreii/Desktop/IPTVGestão/.venv/lib/python3.10/site-packages/django/db/models/lookups.py", line 85, in get_prep_lookup
    return self.lhs.output_field.get_prep_value(self.rhs)
  File "/mnt/c/Users/jreii/Desktop/IPTVGestão/.venv/lib/python3.10/site-packages/django/db/models/fields/__init__.py", line 1464, in get_prep_value
    return self.to_python(value)
  File "/mnt/c/Users/jreii/Desktop/IPTVGestão/.venv/lib/python3.10/site-packages/django/db/models/fields/__init__.py", line 1420, in to_python
    parsed = parse_date(value)
  File "/mnt/c/Users/jreii/Desktop/IPTVGestão/.venv/lib/python3.10/site-packages/django/utils/dateparse.py", line 74, in parse_date
    return datetime.date.fromisoformat(value)
TypeError: fromisoformat: argument must be str
"GET /dashboard/ HTTP/1.1" 500 191419
"GET /dashboard/ HTTP/1.1" 500 191419
Internal Server Error: /dashboard/
Traceback (most recent call last):
  File "/mnt/c/Users/jreii/Desktop/IPTVGestão/.venv/lib/python3.10/site-packages/django/core/handlers/exception.py", line 55, in inner
    response = get_response(request)
  File "/mnt/c/Users/jreii/Desktop/IPTVGestão/.venv/lib/python3.10/site-packages/django/core/handlers/base.py", line 197, in _get_response
    response = wrapped_callback(request, *callback_args, **callback_kwargs)
  File "/mnt/c/Users/jreii/Desktop/IPTVGestão/.venv/lib/python3.10/site-packages/django/views/generic/base.py", line 104, in view
    return self.dispatch(request, *args, **kwargs)
  File "/mnt/c/Users/jreii/Desktop/IPTVGestão/.venv/lib/python3.10/site-packages/django/contrib/auth/mixins.py", line 73, in dispatch
    return super().dispatch(request, *args, **kwargs)
  File "/mnt/c/Users/jreii/Desktop/IPTVGestão/.venv/lib/python3.10/site-packages/django/views/generic/base.py", line 143, in dispatch
    return handler(request, *args, **kwargs)
  File "/mnt/c/Users/jreii/Desktop/IPTVGestão/.venv/lib/python3.10/site-packages/django/views/generic/list.py", line 154, in get
    self.object_list = self.get_queryset()
  File "/mnt/c/Users/jreii/Desktop/IPTVGestão/cadastros/views.py", line 84, in get_queryset
    Cliente.objects.filter(cancelado=False).filter(
  File "/mnt/c/Users/jreii/Desktop/IPTVGestão/.venv/lib/python3.10/site-packages/django/db/models/query.py", line 1436, in filter
    return self._filter_or_exclude(False, args, kwargs)
  File "/mnt/c/Users/jreii/Desktop/IPTVGestão/.venv/lib/python3.10/site-packages/django/db/models/query.py", line 1454, in _filter_or_exclude
    clone._filter_or_exclude_inplace(negate, args, kwargs)
  File "/mnt/c/Users/jreii/Desktop/IPTVGestão/.venv/lib/python3.10/site-packages/django/db/models/query.py", line 1461, in _filter_or_exclude_inplace
    self._query.add_q(Q(*args, **kwargs))
  File "/mnt/c/Users/jreii/Desktop/IPTVGestão/.venv/lib/python3.10/site-packages/django/db/models/sql/query.py", line 1502, in add_q
    clause, _ = self._add_q(q_object, self.used_aliases)
  File "/mnt/c/Users/jreii/Desktop/IPTVGestão/.venv/lib/python3.10/site-packages/django/db/models/sql/query.py", line 1533, in _add_q
    child_clause, needed_inner = self.build_filter(
  File "/mnt/c/Users/jreii/Desktop/IPTVGestão/.venv/lib/python3.10/site-packages/django/db/models/sql/query.py", line 1383, in build_filter
    lookups, parts, reffed_expression = self.solve_lookup_type(arg, summarize)
  File "/mnt/c/Users/jreii/Desktop/IPTVGestão/.venv/lib/python3.10/site-packages/django/db/models/sql/query.py", line 1193, in solve_lookup_type
    _, field, _, lookup_parts = self.names_to_path(lookup_splitted, self.get_meta())
  File "/mnt/c/Users/jreii/Desktop/IPTVGestão/.venv/lib/python3.10/site-packages/django/db/models/sql/query.py", line 1681, in names_to_path
    raise FieldError(
django.core.exceptions.FieldError: Cannot resolve keyword 'mensalidade' into field. Choices are: cancelado, cliente, conta_aplicativo, data_adesao, data_cancelamento, data_pagamento, dispositivo, dispositivo_id, forma_pgto, forma_pgto_id, id, indicado_por, indicado_por_id, mensalidade_cliente, nome, notas, plano, plano_id, servidor, servidor_id, sistema, sistema_id, telas, telas_id, telefone, ultimo_pagamento, usuario, usuario_id
Internal Server Error: /dashboard/
Traceback (most recent call last):
  File "/mnt/c/Users/jreii/Desktop/IPTVGestão/.venv/lib/python3.10/site-packages/django/core/handlers/exception.py", line 55, in inner
    response = get_response(request)
  File "/mnt/c/Users/jreii/Desktop/IPTVGestão/.venv/lib/python3.10/site-packages/django/core/handlers/base.py", line 197, in _get_response
    response = wrapped_callback(request, *callback_args, **callback_kwargs)
  File "/mnt/c/Users/jreii/Desktop/IPTVGestão/.venv/lib/python3.10/site-packages/django/views/generic/base.py", line 104, in view
    return self.dispatch(request, *args, **kwargs)
  File "/mnt/c/Users/jreii/Desktop/IPTVGestão/.venv/lib/python3.10/site-packages/django/contrib/auth/mixins.py", line 73, in dispatch
    return super().dispatch(request, *args, **kwargs)
  File "/mnt/c/Users/jreii/Desktop/IPTVGestão/.venv/lib/python3.10/site-packages/django/views/generic/base.py", line 143, in dispatch
    return handler(request, *args, **kwargs)
  File "/mnt/c/Users/jreii/Desktop/IPTVGestão/.venv/lib/python3.10/site-packages/django/views/generic/list.py", line 154, in get
    self.object_list = self.get_queryset()
  File "/mnt/c/Users/jreii/Desktop/IPTVGestão/cadastros/views.py", line 84, in get_queryset
    Cliente.objects.filter(cancelado=False).filter(
  File "/mnt/c/Users/jreii/Desktop/IPTVGestão/.venv/lib/python3.10/site-packages/django/db/models/query.py", line 1436, in filter
    return self._filter_or_exclude(False, args, kwargs)
  File "/mnt/c/Users/jreii/Desktop/IPTVGestão/.venv/lib/python3.10/site-packages/django/db/models/query.py", line 1454, in _filter_or_exclude
    clone._filter_or_exclude_inplace(negate, args, kwargs)
  File "/mnt/c/Users/jreii/Desktop/IPTVGestão/.venv/lib/python3.10/site-packages/django/db/models/query.py", line 1461, in _filter_or_exclude_inplace
    self._query.add_q(Q(*args, **kwargs))
  File "/mnt/c/Users/jreii/Desktop/IPTVGestão/.venv/lib/python3.10/site-packages/django/db/models/sql/query.py", line 1502, in add_q
    clause, _ = self._add_q(q_object, self.used_aliases)
  File "/mnt/c/Users/jreii/Desktop/IPTVGestão/.venv/lib/python3.10/site-packages/django/db/models/sql/query.py", line 1533, in _add_q
    child_clause, needed_inner = self.build_filter(
  File "/mnt/c/Users/jreii/Desktop/IPTVGestão/.venv/lib/python3.10/site-packages/django/db/models/sql/query.py", line 1383, in build_filter
    lookups, parts, reffed_expression = self.solve_lookup_type(arg, summarize)
  File "/mnt/c/Users/jreii/Desktop/IPTVGestão/.venv/lib/python3.10/site-packages/django/db/models/sql/query.py", line 1193, in solve_lookup_type
    _, field, _, lookup_parts = self.names_to_path(lookup_splitted, self.get_meta())
  File "/mnt/c/Users/jreii/Desktop/IPTVGestão/.venv/lib/python3.10/site-packages/django/db/models/sql/query.py", line 1681, in names_to_path
    raise FieldError(
django.core.exceptions.FieldError: Cannot resolve keyword 'mensalidade' into field. Choices are: cancelado, cliente, conta_aplicativo, data_adesao, data_cancelamento, data_pagamento, dispositivo, dispositivo_id, forma_pgto, forma_pgto_id, id, indicado_por, indicado_por_id, mensalidade_cliente, nome, notas, plano, plano_id, servidor, servidor_id, sistema, sistema_id, telas, telas_id, telefone, ultimo_pagamento, usuario, usuario_id
"GET /dashboard/ HTTP/1.1" 500 123737
"GET /dashboard/ HTTP/1.1" 500 123737
Internal Server Error: /dashboard/
Traceback (most recent call last):
  File "/mnt/c/Users/jreii/Desktop/IPTVGestão/.venv/lib/python3.10/site-packages/django/core/handlers/exception.py", line 55, in inner
    response = get_response(request)
  File "/mnt/c/Users/jreii/Desktop/IPTVGestão/.venv/lib/python3.10/site-packages/django/core/handlers/base.py", line 220, in _get_response
    response = response.render()
  File "/mnt/c/Users/jreii/Desktop/IPTVGestão/.venv/lib/python3.10/site-packages/django/template/response.py", line 114, in render
    self.content = self.rendered_content
  File "/mnt/c/Users/jreii/Desktop/IPTVGestão/.venv/lib/python3.10/site-packages/django/template/response.py", line 90, in rendered_content
    template = self.resolve_template(self.template_name)
  File "/mnt/c/Users/jreii/Desktop/IPTVGestão/.venv/lib/python3.10/site-packages/django/template/response.py", line 72, in resolve_template
    return select_template(template, using=self.using)
  File "/mnt/c/Users/jreii/Desktop/IPTVGestão/.venv/lib/python3.10/site-packages/django/template/loader.py", line 42, in select_template
    return engine.get_template(template_name)
  File "/mnt/c/Users/jreii/Desktop/IPTVGestão/.venv/lib/python3.10/site-packages/django/template/backends/django.py", line 33, in get_template
    return Template(self.engine.get_template(template_name), self)
  File "/mnt/c/Users/jreii/Desktop/IPTVGestão/.venv/lib/python3.10/site-packages/django/template/engine.py", line 175, in get_template
    template, origin = self.find_template(template_name)
  File "/mnt/c/Users/jreii/Desktop/IPTVGestão/.venv/lib/python3.10/site-packages/django/template/engine.py", line 157, in find_template
    template = loader.get_template(name, skip=skip)
  File "/mnt/c/Users/jreii/Desktop/IPTVGestão/.venv/lib/python3.10/site-packages/django/template/loaders/cached.py", line 57, in get_template
    template = super().get_template(template_name, skip)
  File "/mnt/c/Users/jreii/Desktop/IPTVGestão/.venv/lib/python3.10/site-packages/django/template/loaders/base.py", line 28, in get_template
    return Template(
  File "/mnt/c/Users/jreii/Desktop/IPTVGestão/.venv/lib/python3.10/site-packages/django/template/base.py", line 154, in __init__
    self.nodelist = self.compile_nodelist()
  File "/mnt/c/Users/jreii/Desktop/IPTVGestão/.venv/lib/python3.10/site-packages/django/template/base.py", line 200, in compile_nodelist
    return parser.parse()
  File "/mnt/c/Users/jreii/Desktop/IPTVGestão/.venv/lib/python3.10/site-packages/django/template/base.py", line 513, in parse
    raise self.error(token, e)
  File "/mnt/c/Users/jreii/Desktop/IPTVGestão/.venv/lib/python3.10/site-packages/django/template/base.py", line 511, in parse
    compiled_result = compile_func(self, token)
  File "/mnt/c/Users/jreii/Desktop/IPTVGestão/.venv/lib/python3.10/site-packages/django/template/defaulttags.py", line 853, in do_for
    nodelist_loop = parser.parse(
  File "/mnt/c/Users/jreii/Desktop/IPTVGestão/.venv/lib/python3.10/site-packages/django/template/base.py", line 513, in parse
    raise self.error(token, e)
  File "/mnt/c/Users/jreii/Desktop/IPTVGestão/.venv/lib/python3.10/site-packages/django/template/base.py", line 511, in parse
    compiled_result = compile_func(self, token)
  File "/mnt/c/Users/jreii/Desktop/IPTVGestão/.venv/lib/python3.10/site-packages/django/template/defaulttags.py", line 852, in do_for
    sequence = parser.compile_filter(bits[in_index + 1])
  File "/mnt/c/Users/jreii/Desktop/IPTVGestão/.venv/lib/python3.10/site-packages/django/template/base.py", line 600, in compile_filter
    return FilterExpression(token, self)
  File "/mnt/c/Users/jreii/Desktop/IPTVGestão/.venv/lib/python3.10/site-packages/django/template/base.py", line 703, in __init__
    raise TemplateSyntaxError(
django.template.exceptions.TemplateSyntaxError: Could not parse the remainder: '(cancelado=False)' from 'cliente.mensalidade_set.filter(cancelado=False)'
Internal Server Error: /dashboard/
Traceback (most recent call last):
  File "/mnt/c/Users/jreii/Desktop/IPTVGestão/.venv/lib/python3.10/site-packages/django/core/handlers/exception.py", line 55, in inner
    response = get_response(request)
  File "/mnt/c/Users/jreii/Desktop/IPTVGestão/.venv/lib/python3.10/site-packages/django/core/handlers/base.py", line 220, in _get_response
    response = response.render()
  File "/mnt/c/Users/jreii/Desktop/IPTVGestão/.venv/lib/python3.10/site-packages/django/template/response.py", line 114, in render
    self.content = self.rendered_content
  File "/mnt/c/Users/jreii/Desktop/IPTVGestão/.venv/lib/python3.10/site-packages/django/template/response.py", line 90, in rendered_content
    template = self.resolve_template(self.template_name)
  File "/mnt/c/Users/jreii/Desktop/IPTVGestão/.venv/lib/python3.10/site-packages/django/template/response.py", line 72, in resolve_template
    return select_template(template, using=self.using)
  File "/mnt/c/Users/jreii/Desktop/IPTVGestão/.venv/lib/python3.10/site-packages/django/template/loader.py", line 42, in select_template
    return engine.get_template(template_name)
  File "/mnt/c/Users/jreii/Desktop/IPTVGestão/.venv/lib/python3.10/site-packages/django/template/backends/django.py", line 33, in get_template
    return Template(self.engine.get_template(template_name), self)
  File "/mnt/c/Users/jreii/Desktop/IPTVGestão/.venv/lib/python3.10/site-packages/django/template/engine.py", line 175, in get_template
    template, origin = self.find_template(template_name)
  File "/mnt/c/Users/jreii/Desktop/IPTVGestão/.venv/lib/python3.10/site-packages/django/template/engine.py", line 157, in find_template
    template = loader.get_template(name, skip=skip)
  File "/mnt/c/Users/jreii/Desktop/IPTVGestão/.venv/lib/python3.10/site-packages/django/template/loaders/cached.py", line 57, in get_template
    template = super().get_template(template_name, skip)
  File "/mnt/c/Users/jreii/Desktop/IPTVGestão/.venv/lib/python3.10/site-packages/django/template/loaders/base.py", line 28, in get_template
    return Template(
  File "/mnt/c/Users/jreii/Desktop/IPTVGestão/.venv/lib/python3.10/site-packages/django/template/base.py", line 154, in __init__
    self.nodelist = self.compile_nodelist()
  File "/mnt/c/Users/jreii/Desktop/IPTVGestão/.venv/lib/python3.10/site-packages/django/template/base.py", line 200, in compile_nodelist
    return parser.parse()
  File "/mnt/c/Users/jreii/Desktop/IPTVGestão/.venv/lib/python3.10/site-packages/django/template/base.py", line 513, in parse
    raise self.error(token, e)
  File "/mnt/c/Users/jreii/Desktop/IPTVGestão/.venv/lib/python3.10/site-packages/django/template/base.py", line 511, in parse
    compiled_result = compile_func(self, token)
  File "/mnt/c/Users/jreii/Desktop/IPTVGestão/.venv/lib/python3.10/site-packages/django/template/defaulttags.py", line 853, in do_for
    nodelist_loop = parser.parse(
  File "/mnt/c/Users/jreii/Desktop/IPTVGestão/.venv/lib/python3.10/site-packages/django/template/base.py", line 513, in parse
    raise self.error(token, e)
  File "/mnt/c/Users/jreii/Desktop/IPTVGestão/.venv/lib/python3.10/site-packages/django/template/base.py", line 511, in parse
    compiled_result = compile_func(self, token)
  File "/mnt/c/Users/jreii/Desktop/IPTVGestão/.venv/lib/python3.10/site-packages/django/template/defaulttags.py", line 852, in do_for
    sequence = parser.compile_filter(bits[in_index + 1])
  File "/mnt/c/Users/jreii/Desktop/IPTVGestão/.venv/lib/python3.10/site-packages/django/template/base.py", line 600, in compile_filter
    return FilterExpression(token, self)
  File "/mnt/c/Users/jreii/Desktop/IPTVGestão/.venv/lib/python3.10/site-packages/django/template/base.py", line 703, in __init__
    raise TemplateSyntaxError(
django.template.exceptions.TemplateSyntaxError: Could not parse the remainder: '(cancelado=False)' from 'cliente.mensalidade_set.filter(cancelado=False)'
"GET /dashboard/ HTTP/1.1" 500 244225
"GET /dashboard/ HTTP/1.1" 500 244225
Internal Server Error: /dashboard/
Traceback (most recent call last):
  File "/mnt/c/Users/jreii/Desktop/IPTVGestão/.venv/lib/python3.10/site-packages/django/template/base.py", line 505, in parse
    compile_func = self.tags[command]
KeyError: 'continue'

During handling of the above exception, another exception occurred:

Traceback (most recent call last):
  File "/mnt/c/Users/jreii/Desktop/IPTVGestão/.venv/lib/python3.10/site-packages/django/core/handlers/exception.py", line 55, in inner
    response = get_response(request)
  File "/mnt/c/Users/jreii/Desktop/IPTVGestão/.venv/lib/python3.10/site-packages/django/core/handlers/base.py", line 220, in _get_response
    response = response.render()
  File "/mnt/c/Users/jreii/Desktop/IPTVGestão/.venv/lib/python3.10/site-packages/django/template/response.py", line 114, in render
    self.content = self.rendered_content
  File "/mnt/c/Users/jreii/Desktop/IPTVGestão/.venv/lib/python3.10/site-packages/django/template/response.py", line 90, in rendered_content
    template = self.resolve_template(self.template_name)
  File "/mnt/c/Users/jreii/Desktop/IPTVGestão/.venv/lib/python3.10/site-packages/django/template/response.py", line 72, in resolve_template
    return select_template(template, using=self.using)
  File "/mnt/c/Users/jreii/Desktop/IPTVGestão/.venv/lib/python3.10/site-packages/django/template/loader.py", line 42, in select_template
    return engine.get_template(template_name)
  File "/mnt/c/Users/jreii/Desktop/IPTVGestão/.venv/lib/python3.10/site-packages/django/template/backends/django.py", line 33, in get_template
    return Template(self.engine.get_template(template_name), self)
  File "/mnt/c/Users/jreii/Desktop/IPTVGestão/.venv/lib/python3.10/site-packages/django/template/engine.py", line 175, in get_template
    template, origin = self.find_template(template_name)
  File "/mnt/c/Users/jreii/Desktop/IPTVGestão/.venv/lib/python3.10/site-packages/django/template/engine.py", line 157, in find_template
    template = loader.get_template(name, skip=skip)
  File "/mnt/c/Users/jreii/Desktop/IPTVGestão/.venv/lib/python3.10/site-packages/django/template/loaders/cached.py", line 57, in get_template
    template = super().get_template(template_name, skip)
  File "/mnt/c/Users/jreii/Desktop/IPTVGestão/.venv/lib/python3.10/site-packages/django/template/loaders/base.py", line 28, in get_template
    return Template(
  File "/mnt/c/Users/jreii/Desktop/IPTVGestão/.venv/lib/python3.10/site-packages/django/template/base.py", line 154, in __init__
    self.nodelist = self.compile_nodelist()
  File "/mnt/c/Users/jreii/Desktop/IPTVGestão/.venv/lib/python3.10/site-packages/django/template/base.py", line 200, in compile_nodelist
    return parser.parse()
  File "/mnt/c/Users/jreii/Desktop/IPTVGestão/.venv/lib/python3.10/site-packages/django/template/base.py", line 513, in parse
    raise self.error(token, e)
  File "/mnt/c/Users/jreii/Desktop/IPTVGestão/.venv/lib/python3.10/site-packages/django/template/base.py", line 511, in parse
    compiled_result = compile_func(self, token)
  File "/mnt/c/Users/jreii/Desktop/IPTVGestão/.venv/lib/python3.10/site-packages/django/template/defaulttags.py", line 853, in do_for
    nodelist_loop = parser.parse(
  File "/mnt/c/Users/jreii/Desktop/IPTVGestão/.venv/lib/python3.10/site-packages/django/template/base.py", line 513, in parse
    raise self.error(token, e)
  File "/mnt/c/Users/jreii/Desktop/IPTVGestão/.venv/lib/python3.10/site-packages/django/template/base.py", line 511, in parse
    compiled_result = compile_func(self, token)
  File "/mnt/c/Users/jreii/Desktop/IPTVGestão/.venv/lib/python3.10/site-packages/django/template/defaulttags.py", line 853, in do_for
    nodelist_loop = parser.parse(
  File "/mnt/c/Users/jreii/Desktop/IPTVGestão/.venv/lib/python3.10/site-packages/django/template/base.py", line 513, in parse
    raise self.error(token, e)
  File "/mnt/c/Users/jreii/Desktop/IPTVGestão/.venv/lib/python3.10/site-packages/django/template/base.py", line 511, in parse
    compiled_result = compile_func(self, token)
  File "/mnt/c/Users/jreii/Desktop/IPTVGestão/.venv/lib/python3.10/site-packages/django/template/defaulttags.py", line 953, in do_if
    nodelist = parser.parse(("elif", "else", "endif"))
  File "/mnt/c/Users/jreii/Desktop/IPTVGestão/.venv/lib/python3.10/site-packages/django/template/base.py", line 507, in parse
    self.invalid_block_tag(token, command, parse_until)
  File "/mnt/c/Users/jreii/Desktop/IPTVGestão/.venv/lib/python3.10/site-packages/django/template/base.py", line 558, in invalid_block_tag
    raise self.error(
django.template.exceptions.TemplateSyntaxError: Invalid block tag on line 346: 'continue', expected 'elif', 'else' or 'endif'. Did you forget to register or load this tag?
Internal Server Error: /dashboard/
Traceback (most recent call last):
  File "/mnt/c/Users/jreii/Desktop/IPTVGestão/.venv/lib/python3.10/site-packages/django/template/base.py", line 505, in parse
    compile_func = self.tags[command]
KeyError: 'continue'

During handling of the above exception, another exception occurred:

Traceback (most recent call last):
  File "/mnt/c/Users/jreii/Desktop/IPTVGestão/.venv/lib/python3.10/site-packages/django/core/handlers/exception.py", line 55, in inner
    response = get_response(request)
  File "/mnt/c/Users/jreii/Desktop/IPTVGestão/.venv/lib/python3.10/site-packages/django/core/handlers/base.py", line 220, in _get_response
    response = response.render()
  File "/mnt/c/Users/jreii/Desktop/IPTVGestão/.venv/lib/python3.10/site-packages/django/template/response.py", line 114, in render
    self.content = self.rendered_content
  File "/mnt/c/Users/jreii/Desktop/IPTVGestão/.venv/lib/python3.10/site-packages/django/template/response.py", line 90, in rendered_content
    template = self.resolve_template(self.template_name)
  File "/mnt/c/Users/jreii/Desktop/IPTVGestão/.venv/lib/python3.10/site-packages/django/template/response.py", line 72, in resolve_template
    return select_template(template, using=self.using)
  File "/mnt/c/Users/jreii/Desktop/IPTVGestão/.venv/lib/python3.10/site-packages/django/template/loader.py", line 42, in select_template
    return engine.get_template(template_name)
  File "/mnt/c/Users/jreii/Desktop/IPTVGestão/.venv/lib/python3.10/site-packages/django/template/backends/django.py", line 33, in get_template
    return Template(self.engine.get_template(template_name), self)
  File "/mnt/c/Users/jreii/Desktop/IPTVGestão/.venv/lib/python3.10/site-packages/django/template/engine.py", line 175, in get_template
    template, origin = self.find_template(template_name)
  File "/mnt/c/Users/jreii/Desktop/IPTVGestão/.venv/lib/python3.10/site-packages/django/template/engine.py", line 157, in find_template
    template = loader.get_template(name, skip=skip)
  File "/mnt/c/Users/jreii/Desktop/IPTVGestão/.venv/lib/python3.10/site-packages/django/template/loaders/cached.py", line 57, in get_template
    template = super().get_template(template_name, skip)
  File "/mnt/c/Users/jreii/Desktop/IPTVGestão/.venv/lib/python3.10/site-packages/django/template/loaders/base.py", line 28, in get_template
    return Template(
  File "/mnt/c/Users/jreii/Desktop/IPTVGestão/.venv/lib/python3.10/site-packages/django/template/base.py", line 154, in __init__
    self.nodelist = self.compile_nodelist()
  File "/mnt/c/Users/jreii/Desktop/IPTVGestão/.venv/lib/python3.10/site-packages/django/template/base.py", line 200, in compile_nodelist
    return parser.parse()
  File "/mnt/c/Users/jreii/Desktop/IPTVGestão/.venv/lib/python3.10/site-packages/django/template/base.py", line 513, in parse
    raise self.error(token, e)
  File "/mnt/c/Users/jreii/Desktop/IPTVGestão/.venv/lib/python3.10/site-packages/django/template/base.py", line 511, in parse
    compiled_result = compile_func(self, token)
  File "/mnt/c/Users/jreii/Desktop/IPTVGestão/.venv/lib/python3.10/site-packages/django/template/defaulttags.py", line 853, in do_for
    nodelist_loop = parser.parse(
  File "/mnt/c/Users/jreii/Desktop/IPTVGestão/.venv/lib/python3.10/site-packages/django/template/base.py", line 513, in parse
    raise self.error(token, e)
  File "/mnt/c/Users/jreii/Desktop/IPTVGestão/.venv/lib/python3.10/site-packages/django/template/base.py", line 511, in parse
    compiled_result = compile_func(self, token)
  File "/mnt/c/Users/jreii/Desktop/IPTVGestão/.venv/lib/python3.10/site-packages/django/template/defaulttags.py", line 853, in do_for
    nodelist_loop = parser.parse(
  File "/mnt/c/Users/jreii/Desktop/IPTVGestão/.venv/lib/python3.10/site-packages/django/template/base.py", line 513, in parse
    raise self.error(token, e)
  File "/mnt/c/Users/jreii/Desktop/IPTVGestão/.venv/lib/python3.10/site-packages/django/template/base.py", line 511, in parse
    compiled_result = compile_func(self, token)
  File "/mnt/c/Users/jreii/Desktop/IPTVGestão/.venv/lib/python3.10/site-packages/django/template/defaulttags.py", line 953, in do_if
    nodelist = parser.parse(("elif", "else", "endif"))
  File "/mnt/c/Users/jreii/Desktop/IPTVGestão/.venv/lib/python3.10/site-packages/django/template/base.py", line 507, in parse
    self.invalid_block_tag(token, command, parse_until)
  File "/mnt/c/Users/jreii/Desktop/IPTVGestão/.venv/lib/python3.10/site-packages/django/template/base.py", line 558, in invalid_block_tag
    raise self.error(
django.template.exceptions.TemplateSyntaxError: Invalid block tag on line 346: 'continue', expected 'elif', 'else' or 'endif'. Did you forget to register or load this tag?
"GET /dashboard/ HTTP/1.1" 500 287363
"GET /dashboard/ HTTP/1.1" 500 287363
Internal Server Error: /dashboard/
Traceback (most recent call last):
  File "/mnt/c/Users/jreii/Desktop/IPTVGestão/.venv/lib/python3.10/site-packages/django/template/base.py", line 505, in parse
    compile_func = self.tags[command]
KeyError: 'endif'

During handling of the above exception, another exception occurred:

Traceback (most recent call last):
  File "/mnt/c/Users/jreii/Desktop/IPTVGestão/.venv/lib/python3.10/site-packages/django/core/handlers/exception.py", line 55, in inner
    response = get_response(request)
  File "/mnt/c/Users/jreii/Desktop/IPTVGestão/.venv/lib/python3.10/site-packages/django/core/handlers/base.py", line 220, in _get_response
    response = response.render()
  File "/mnt/c/Users/jreii/Desktop/IPTVGestão/.venv/lib/python3.10/site-packages/django/template/response.py", line 114, in render
    self.content = self.rendered_content
  File "/mnt/c/Users/jreii/Desktop/IPTVGestão/.venv/lib/python3.10/site-packages/django/template/response.py", line 90, in rendered_content
    template = self.resolve_template(self.template_name)
  File "/mnt/c/Users/jreii/Desktop/IPTVGestão/.venv/lib/python3.10/site-packages/django/template/response.py", line 72, in resolve_template
    return select_template(template, using=self.using)
  File "/mnt/c/Users/jreii/Desktop/IPTVGestão/.venv/lib/python3.10/site-packages/django/template/loader.py", line 42, in select_template
    return engine.get_template(template_name)
  File "/mnt/c/Users/jreii/Desktop/IPTVGestão/.venv/lib/python3.10/site-packages/django/template/backends/django.py", line 33, in get_template
    return Template(self.engine.get_template(template_name), self)
  File "/mnt/c/Users/jreii/Desktop/IPTVGestão/.venv/lib/python3.10/site-packages/django/template/engine.py", line 175, in get_template
    template, origin = self.find_template(template_name)
  File "/mnt/c/Users/jreii/Desktop/IPTVGestão/.venv/lib/python3.10/site-packages/django/template/engine.py", line 157, in find_template
    template = loader.get_template(name, skip=skip)
  File "/mnt/c/Users/jreii/Desktop/IPTVGestão/.venv/lib/python3.10/site-packages/django/template/loaders/cached.py", line 57, in get_template
    template = super().get_template(template_name, skip)
  File "/mnt/c/Users/jreii/Desktop/IPTVGestão/.venv/lib/python3.10/site-packages/django/template/loaders/base.py", line 28, in get_template
    return Template(
  File "/mnt/c/Users/jreii/Desktop/IPTVGestão/.venv/lib/python3.10/site-packages/django/template/base.py", line 154, in __init__
    self.nodelist = self.compile_nodelist()
  File "/mnt/c/Users/jreii/Desktop/IPTVGestão/.venv/lib/python3.10/site-packages/django/template/base.py", line 200, in compile_nodelist
    return parser.parse()
  File "/mnt/c/Users/jreii/Desktop/IPTVGestão/.venv/lib/python3.10/site-packages/django/template/base.py", line 513, in parse
    raise self.error(token, e)
  File "/mnt/c/Users/jreii/Desktop/IPTVGestão/.venv/lib/python3.10/site-packages/django/template/base.py", line 511, in parse
    compiled_result = compile_func(self, token)
  File "/mnt/c/Users/jreii/Desktop/IPTVGestão/.venv/lib/python3.10/site-packages/django/template/defaulttags.py", line 853, in do_for
    nodelist_loop = parser.parse(
  File "/mnt/c/Users/jreii/Desktop/IPTVGestão/.venv/lib/python3.10/site-packages/django/template/base.py", line 513, in parse
    raise self.error(token, e)
  File "/mnt/c/Users/jreii/Desktop/IPTVGestão/.venv/lib/python3.10/site-packages/django/template/base.py", line 511, in parse
    compiled_result = compile_func(self, token)
  File "/mnt/c/Users/jreii/Desktop/IPTVGestão/.venv/lib/python3.10/site-packages/django/template/defaulttags.py", line 853, in do_for
    nodelist_loop = parser.parse(
  File "/mnt/c/Users/jreii/Desktop/IPTVGestão/.venv/lib/python3.10/site-packages/django/template/base.py", line 507, in parse
    self.invalid_block_tag(token, command, parse_until)
  File "/mnt/c/Users/jreii/Desktop/IPTVGestão/.venv/lib/python3.10/site-packages/django/template/base.py", line 558, in invalid_block_tag
    raise self.error(
django.template.exceptions.TemplateSyntaxError: Invalid block tag on line 382: 'endif', expected 'empty' or 'endfor'. Did you forget to register or load this tag?
Internal Server Error: /dashboard/
Traceback (most recent call last):
  File "/mnt/c/Users/jreii/Desktop/IPTVGestão/.venv/lib/python3.10/site-packages/django/template/base.py", line 505, in parse
    compile_func = self.tags[command]
KeyError: 'endif'

During handling of the above exception, another exception occurred:

Traceback (most recent call last):
  File "/mnt/c/Users/jreii/Desktop/IPTVGestão/.venv/lib/python3.10/site-packages/django/core/handlers/exception.py", line 55, in inner
    response = get_response(request)
  File "/mnt/c/Users/jreii/Desktop/IPTVGestão/.venv/lib/python3.10/site-packages/django/core/handlers/base.py", line 220, in _get_response
    response = response.render()
  File "/mnt/c/Users/jreii/Desktop/IPTVGestão/.venv/lib/python3.10/site-packages/django/template/response.py", line 114, in render
    self.content = self.rendered_content
  File "/mnt/c/Users/jreii/Desktop/IPTVGestão/.venv/lib/python3.10/site-packages/django/template/response.py", line 90, in rendered_content
    template = self.resolve_template(self.template_name)
  File "/mnt/c/Users/jreii/Desktop/IPTVGestão/.venv/lib/python3.10/site-packages/django/template/response.py", line 72, in resolve_template
    return select_template(template, using=self.using)
  File "/mnt/c/Users/jreii/Desktop/IPTVGestão/.venv/lib/python3.10/site-packages/django/template/loader.py", line 42, in select_template
    return engine.get_template(template_name)
  File "/mnt/c/Users/jreii/Desktop/IPTVGestão/.venv/lib/python3.10/site-packages/django/template/backends/django.py", line 33, in get_template
    return Template(self.engine.get_template(template_name), self)
  File "/mnt/c/Users/jreii/Desktop/IPTVGestão/.venv/lib/python3.10/site-packages/django/template/engine.py", line 175, in get_template
    template, origin = self.find_template(template_name)
  File "/mnt/c/Users/jreii/Desktop/IPTVGestão/.venv/lib/python3.10/site-packages/django/template/engine.py", line 157, in find_template
    template = loader.get_template(name, skip=skip)
  File "/mnt/c/Users/jreii/Desktop/IPTVGestão/.venv/lib/python3.10/site-packages/django/template/loaders/cached.py", line 57, in get_template
    template = super().get_template(template_name, skip)
  File "/mnt/c/Users/jreii/Desktop/IPTVGestão/.venv/lib/python3.10/site-packages/django/template/loaders/base.py", line 28, in get_template
    return Template(
  File "/mnt/c/Users/jreii/Desktop/IPTVGestão/.venv/lib/python3.10/site-packages/django/template/base.py", line 154, in __init__
    self.nodelist = self.compile_nodelist()
  File "/mnt/c/Users/jreii/Desktop/IPTVGestão/.venv/lib/python3.10/site-packages/django/template/base.py", line 200, in compile_nodelist
    return parser.parse()
  File "/mnt/c/Users/jreii/Desktop/IPTVGestão/.venv/lib/python3.10/site-packages/django/template/base.py", line 513, in parse
    raise self.error(token, e)
  File "/mnt/c/Users/jreii/Desktop/IPTVGestão/.venv/lib/python3.10/site-packages/django/template/base.py", line 511, in parse
    compiled_result = compile_func(self, token)
  File "/mnt/c/Users/jreii/Desktop/IPTVGestão/.venv/lib/python3.10/site-packages/django/template/defaulttags.py", line 853, in do_for
    nodelist_loop = parser.parse(
  File "/mnt/c/Users/jreii/Desktop/IPTVGestão/.venv/lib/python3.10/site-packages/django/template/base.py", line 513, in parse
    raise self.error(token, e)
  File "/mnt/c/Users/jreii/Desktop/IPTVGestão/.venv/lib/python3.10/site-packages/django/template/base.py", line 511, in parse
    compiled_result = compile_func(self, token)
  File "/mnt/c/Users/jreii/Desktop/IPTVGestão/.venv/lib/python3.10/site-packages/django/template/defaulttags.py", line 853, in do_for
    nodelist_loop = parser.parse(
  File "/mnt/c/Users/jreii/Desktop/IPTVGestão/.venv/lib/python3.10/site-packages/django/template/base.py", line 507, in parse
    self.invalid_block_tag(token, command, parse_until)
  File "/mnt/c/Users/jreii/Desktop/IPTVGestão/.venv/lib/python3.10/site-packages/django/template/base.py", line 558, in invalid_block_tag
    raise self.error(
django.template.exceptions.TemplateSyntaxError: Invalid block tag on line 382: 'endif', expected 'empty' or 'endfor'. Did you forget to register or load this tag?
"GET /dashboard/ HTTP/1.1" 500 257492
"GET /dashboard/ HTTP/1.1" 500 257492
[2023-05-19 13:35:03.557895-03:00][USER][admin] [IP][127.0.0.1] [ERRO][NOT NULL constraint failed: cadastros_contadoaplicativo.app_id]
Traceback (most recent call last):
  File "/mnt/c/Users/jreii/Desktop/IPTVGestão/.venv/lib/python3.10/site-packages/django/db/backends/utils.py", line 89, in _execute
    return self.cursor.execute(sql, params)
  File "/mnt/c/Users/jreii/Desktop/IPTVGestão/.venv/lib/python3.10/site-packages/django/db/backends/sqlite3/base.py", line 328, in execute
    return super().execute(query, params)
sqlite3.IntegrityError: NOT NULL constraint failed: cadastros_contadoaplicativo.app_id

The above exception was the direct cause of the following exception:

Traceback (most recent call last):
  File "/mnt/c/Users/jreii/Desktop/IPTVGestão/cadastros/views.py", line 594, in ImportarClientes
    dados_do_app.save()
  File "/mnt/c/Users/jreii/Desktop/IPTVGestão/cadastros/models.py", line 252, in save
    super(ContaDoAplicativo, self).save(*args, **kwargs)
  File "/mnt/c/Users/jreii/Desktop/IPTVGestão/.venv/lib/python3.10/site-packages/django/db/models/base.py", line 814, in save
    self.save_base(
  File "/mnt/c/Users/jreii/Desktop/IPTVGestão/.venv/lib/python3.10/site-packages/django/db/models/base.py", line 877, in save_base
    updated = self._save_table(
  File "/mnt/c/Users/jreii/Desktop/IPTVGestão/.venv/lib/python3.10/site-packages/django/db/models/base.py", line 1020, in _save_table
    results = self._do_insert(
  File "/mnt/c/Users/jreii/Desktop/IPTVGestão/.venv/lib/python3.10/site-packages/django/db/models/base.py", line 1061, in _do_insert
    return manager._insert(
  File "/mnt/c/Users/jreii/Desktop/IPTVGestão/.venv/lib/python3.10/site-packages/django/db/models/manager.py", line 87, in manager_method
    return getattr(self.get_queryset(), name)(*args, **kwargs)
  File "/mnt/c/Users/jreii/Desktop/IPTVGestão/.venv/lib/python3.10/site-packages/django/db/models/query.py", line 1805, in _insert
    return query.get_compiler(using=using).execute_sql(returning_fields)
  File "/mnt/c/Users/jreii/Desktop/IPTVGestão/.venv/lib/python3.10/site-packages/django/db/models/sql/compiler.py", line 1820, in execute_sql
    cursor.execute(sql, params)
  File "/mnt/c/Users/jreii/Desktop/IPTVGestão/.venv/lib/python3.10/site-packages/django/db/backends/utils.py", line 102, in execute
    return super().execute(sql, params)
  File "/mnt/c/Users/jreii/Desktop/IPTVGestão/.venv/lib/python3.10/site-packages/django/db/backends/utils.py", line 67, in execute
    return self._execute_with_wrappers(
  File "/mnt/c/Users/jreii/Desktop/IPTVGestão/.venv/lib/python3.10/site-packages/django/db/backends/utils.py", line 80, in _execute_with_wrappers
    return executor(sql, params, many, context)
  File "/mnt/c/Users/jreii/Desktop/IPTVGestão/.venv/lib/python3.10/site-packages/django/db/backends/utils.py", line 84, in _execute
    with self.db.wrap_database_errors:
  File "/mnt/c/Users/jreii/Desktop/IPTVGestão/.venv/lib/python3.10/site-packages/django/db/utils.py", line 91, in __exit__
    raise dj_exc_value.with_traceback(traceback) from exc_value
  File "/mnt/c/Users/jreii/Desktop/IPTVGestão/.venv/lib/python3.10/site-packages/django/db/backends/utils.py", line 89, in _execute
    return self.cursor.execute(sql, params)
  File "/mnt/c/Users/jreii/Desktop/IPTVGestão/.venv/lib/python3.10/site-packages/django/db/backends/sqlite3/base.py", line 328, in execute
    return super().execute(query, params)
django.db.utils.IntegrityError: NOT NULL constraint failed: cadastros_contadoaplicativo.app_id
[2023-05-19 13:35:03.700391-03:00][USER][admin] [IP][127.0.0.1] [ERRO][NOT NULL constraint failed: cadastros_contadoaplicativo.app_id]
Traceback (most recent call last):
  File "/mnt/c/Users/jreii/Desktop/IPTVGestão/.venv/lib/python3.10/site-packages/django/db/backends/utils.py", line 89, in _execute
    return self.cursor.execute(sql, params)
  File "/mnt/c/Users/jreii/Desktop/IPTVGestão/.venv/lib/python3.10/site-packages/django/db/backends/sqlite3/base.py", line 328, in execute
    return super().execute(query, params)
sqlite3.IntegrityError: NOT NULL constraint failed: cadastros_contadoaplicativo.app_id

The above exception was the direct cause of the following exception:

Traceback (most recent call last):
  File "/mnt/c/Users/jreii/Desktop/IPTVGestão/cadastros/views.py", line 594, in ImportarClientes
    dados_do_app.save()
  File "/mnt/c/Users/jreii/Desktop/IPTVGestão/cadastros/models.py", line 252, in save
    super(ContaDoAplicativo, self).save(*args, **kwargs)
  File "/mnt/c/Users/jreii/Desktop/IPTVGestão/.venv/lib/python3.10/site-packages/django/db/models/base.py", line 814, in save
    self.save_base(
  File "/mnt/c/Users/jreii/Desktop/IPTVGestão/.venv/lib/python3.10/site-packages/django/db/models/base.py", line 877, in save_base
    updated = self._save_table(
  File "/mnt/c/Users/jreii/Desktop/IPTVGestão/.venv/lib/python3.10/site-packages/django/db/models/base.py", line 1020, in _save_table
    results = self._do_insert(
  File "/mnt/c/Users/jreii/Desktop/IPTVGestão/.venv/lib/python3.10/site-packages/django/db/models/base.py", line 1061, in _do_insert
    return manager._insert(
  File "/mnt/c/Users/jreii/Desktop/IPTVGestão/.venv/lib/python3.10/site-packages/django/db/models/manager.py", line 87, in manager_method
    return getattr(self.get_queryset(), name)(*args, **kwargs)
  File "/mnt/c/Users/jreii/Desktop/IPTVGestão/.venv/lib/python3.10/site-packages/django/db/models/query.py", line 1805, in _insert
    return query.get_compiler(using=using).execute_sql(returning_fields)
  File "/mnt/c/Users/jreii/Desktop/IPTVGestão/.venv/lib/python3.10/site-packages/django/db/models/sql/compiler.py", line 1820, in execute_sql
    cursor.execute(sql, params)
  File "/mnt/c/Users/jreii/Desktop/IPTVGestão/.venv/lib/python3.10/site-packages/django/db/backends/utils.py", line 102, in execute
    return super().execute(sql, params)
  File "/mnt/c/Users/jreii/Desktop/IPTVGestão/.venv/lib/python3.10/site-packages/django/db/backends/utils.py", line 67, in execute
    return self._execute_with_wrappers(
  File "/mnt/c/Users/jreii/Desktop/IPTVGestão/.venv/lib/python3.10/site-packages/django/db/backends/utils.py", line 80, in _execute_with_wrappers
    return executor(sql, params, many, context)
  File "/mnt/c/Users/jreii/Desktop/IPTVGestão/.venv/lib/python3.10/site-packages/django/db/backends/utils.py", line 84, in _execute
    with self.db.wrap_database_errors:
  File "/mnt/c/Users/jreii/Desktop/IPTVGestão/.venv/lib/python3.10/site-packages/django/db/utils.py", line 91, in __exit__
    raise dj_exc_value.with_traceback(traceback) from exc_value
  File "/mnt/c/Users/jreii/Desktop/IPTVGestão/.venv/lib/python3.10/site-packages/django/db/backends/utils.py", line 89, in _execute
    return self.cursor.execute(sql, params)
  File "/mnt/c/Users/jreii/Desktop/IPTVGestão/.venv/lib/python3.10/site-packages/django/db/backends/sqlite3/base.py", line 328, in execute
    return super().execute(query, params)
django.db.utils.IntegrityError: NOT NULL constraint failed: cadastros_contadoaplicativo.app_id
[2023-05-19 13:35:03.994230-03:00][USER][admin] [IP][127.0.0.1] [ERRO][NOT NULL constraint failed: cadastros_contadoaplicativo.app_id]
Traceback (most recent call last):
  File "/mnt/c/Users/jreii/Desktop/IPTVGestão/.venv/lib/python3.10/site-packages/django/db/backends/utils.py", line 89, in _execute
    return self.cursor.execute(sql, params)
  File "/mnt/c/Users/jreii/Desktop/IPTVGestão/.venv/lib/python3.10/site-packages/django/db/backends/sqlite3/base.py", line 328, in execute
    return super().execute(query, params)
sqlite3.IntegrityError: NOT NULL constraint failed: cadastros_contadoaplicativo.app_id

The above exception was the direct cause of the following exception:

Traceback (most recent call last):
  File "/mnt/c/Users/jreii/Desktop/IPTVGestão/cadastros/views.py", line 594, in ImportarClientes
    dados_do_app.save()
  File "/mnt/c/Users/jreii/Desktop/IPTVGestão/cadastros/models.py", line 252, in save
    super(ContaDoAplicativo, self).save(*args, **kwargs)
  File "/mnt/c/Users/jreii/Desktop/IPTVGestão/.venv/lib/python3.10/site-packages/django/db/models/base.py", line 814, in save
    self.save_base(
  File "/mnt/c/Users/jreii/Desktop/IPTVGestão/.venv/lib/python3.10/site-packages/django/db/models/base.py", line 877, in save_base
    updated = self._save_table(
  File "/mnt/c/Users/jreii/Desktop/IPTVGestão/.venv/lib/python3.10/site-packages/django/db/models/base.py", line 1020, in _save_table
    results = self._do_insert(
  File "/mnt/c/Users/jreii/Desktop/IPTVGestão/.venv/lib/python3.10/site-packages/django/db/models/base.py", line 1061, in _do_insert
    return manager._insert(
  File "/mnt/c/Users/jreii/Desktop/IPTVGestão/.venv/lib/python3.10/site-packages/django/db/models/manager.py", line 87, in manager_method
    return getattr(self.get_queryset(), name)(*args, **kwargs)
  File "/mnt/c/Users/jreii/Desktop/IPTVGestão/.venv/lib/python3.10/site-packages/django/db/models/query.py", line 1805, in _insert
    return query.get_compiler(using=using).execute_sql(returning_fields)
  File "/mnt/c/Users/jreii/Desktop/IPTVGestão/.venv/lib/python3.10/site-packages/django/db/models/sql/compiler.py", line 1820, in execute_sql
    cursor.execute(sql, params)
  File "/mnt/c/Users/jreii/Desktop/IPTVGestão/.venv/lib/python3.10/site-packages/django/db/backends/utils.py", line 102, in execute
    return super().execute(sql, params)
  File "/mnt/c/Users/jreii/Desktop/IPTVGestão/.venv/lib/python3.10/site-packages/django/db/backends/utils.py", line 67, in execute
    return self._execute_with_wrappers(
  File "/mnt/c/Users/jreii/Desktop/IPTVGestão/.venv/lib/python3.10/site-packages/django/db/backends/utils.py", line 80, in _execute_with_wrappers
    return executor(sql, params, many, context)
  File "/mnt/c/Users/jreii/Desktop/IPTVGestão/.venv/lib/python3.10/site-packages/django/db/backends/utils.py", line 84, in _execute
    with self.db.wrap_database_errors:
  File "/mnt/c/Users/jreii/Desktop/IPTVGestão/.venv/lib/python3.10/site-packages/django/db/utils.py", line 91, in __exit__
    raise dj_exc_value.with_traceback(traceback) from exc_value
  File "/mnt/c/Users/jreii/Desktop/IPTVGestão/.venv/lib/python3.10/site-packages/django/db/backends/utils.py", line 89, in _execute
    return self.cursor.execute(sql, params)
  File "/mnt/c/Users/jreii/Desktop/IPTVGestão/.venv/lib/python3.10/site-packages/django/db/backends/sqlite3/base.py", line 328, in execute
    return super().execute(query, params)
django.db.utils.IntegrityError: NOT NULL constraint failed: cadastros_contadoaplicativo.app_id
[2023-05-19 13:35:04.005372-03:00][USER][admin] [IP][127.0.0.1] [ERRO][NOT NULL constraint failed: cadastros_contadoaplicativo.app_id]
Traceback (most recent call last):
  File "/mnt/c/Users/jreii/Desktop/IPTVGestão/.venv/lib/python3.10/site-packages/django/db/backends/utils.py", line 89, in _execute
    return self.cursor.execute(sql, params)
  File "/mnt/c/Users/jreii/Desktop/IPTVGestão/.venv/lib/python3.10/site-packages/django/db/backends/sqlite3/base.py", line 328, in execute
    return super().execute(query, params)
sqlite3.IntegrityError: NOT NULL constraint failed: cadastros_contadoaplicativo.app_id

The above exception was the direct cause of the following exception:

Traceback (most recent call last):
  File "/mnt/c/Users/jreii/Desktop/IPTVGestão/cadastros/views.py", line 594, in ImportarClientes
    dados_do_app.save()
  File "/mnt/c/Users/jreii/Desktop/IPTVGestão/cadastros/models.py", line 252, in save
    super(ContaDoAplicativo, self).save(*args, **kwargs)
  File "/mnt/c/Users/jreii/Desktop/IPTVGestão/.venv/lib/python3.10/site-packages/django/db/models/base.py", line 814, in save
    self.save_base(
  File "/mnt/c/Users/jreii/Desktop/IPTVGestão/.venv/lib/python3.10/site-packages/django/db/models/base.py", line 877, in save_base
    updated = self._save_table(
  File "/mnt/c/Users/jreii/Desktop/IPTVGestão/.venv/lib/python3.10/site-packages/django/db/models/base.py", line 1020, in _save_table
    results = self._do_insert(
  File "/mnt/c/Users/jreii/Desktop/IPTVGestão/.venv/lib/python3.10/site-packages/django/db/models/base.py", line 1061, in _do_insert
    return manager._insert(
  File "/mnt/c/Users/jreii/Desktop/IPTVGestão/.venv/lib/python3.10/site-packages/django/db/models/manager.py", line 87, in manager_method
    return getattr(self.get_queryset(), name)(*args, **kwargs)
  File "/mnt/c/Users/jreii/Desktop/IPTVGestão/.venv/lib/python3.10/site-packages/django/db/models/query.py", line 1805, in _insert
    return query.get_compiler(using=using).execute_sql(returning_fields)
  File "/mnt/c/Users/jreii/Desktop/IPTVGestão/.venv/lib/python3.10/site-packages/django/db/models/sql/compiler.py", line 1820, in execute_sql
    cursor.execute(sql, params)
  File "/mnt/c/Users/jreii/Desktop/IPTVGestão/.venv/lib/python3.10/site-packages/django/db/backends/utils.py", line 102, in execute
    return super().execute(sql, params)
  File "/mnt/c/Users/jreii/Desktop/IPTVGestão/.venv/lib/python3.10/site-packages/django/db/backends/utils.py", line 67, in execute
    return self._execute_with_wrappers(
  File "/mnt/c/Users/jreii/Desktop/IPTVGestão/.venv/lib/python3.10/site-packages/django/db/backends/utils.py", line 80, in _execute_with_wrappers
    return executor(sql, params, many, context)
  File "/mnt/c/Users/jreii/Desktop/IPTVGestão/.venv/lib/python3.10/site-packages/django/db/backends/utils.py", line 84, in _execute
    with self.db.wrap_database_errors:
  File "/mnt/c/Users/jreii/Desktop/IPTVGestão/.venv/lib/python3.10/site-packages/django/db/utils.py", line 91, in __exit__
    raise dj_exc_value.with_traceback(traceback) from exc_value
  File "/mnt/c/Users/jreii/Desktop/IPTVGestão/.venv/lib/python3.10/site-packages/django/db/backends/utils.py", line 89, in _execute
    return self.cursor.execute(sql, params)
  File "/mnt/c/Users/jreii/Desktop/IPTVGestão/.venv/lib/python3.10/site-packages/django/db/backends/sqlite3/base.py", line 328, in execute
    return super().execute(query, params)
django.db.utils.IntegrityError: NOT NULL constraint failed: cadastros_contadoaplicativo.app_id
[2023-05-19 13:35:04.630507-03:00][USER][admin] [IP][127.0.0.1] [ERRO][NOT NULL constraint failed: cadastros_contadoaplicativo.app_id]
Traceback (most recent call last):
  File "/mnt/c/Users/jreii/Desktop/IPTVGestão/.venv/lib/python3.10/site-packages/django/db/backends/utils.py", line 89, in _execute
    return self.cursor.execute(sql, params)
  File "/mnt/c/Users/jreii/Desktop/IPTVGestão/.venv/lib/python3.10/site-packages/django/db/backends/sqlite3/base.py", line 328, in execute
    return super().execute(query, params)
sqlite3.IntegrityError: NOT NULL constraint failed: cadastros_contadoaplicativo.app_id

The above exception was the direct cause of the following exception:

Traceback (most recent call last):
  File "/mnt/c/Users/jreii/Desktop/IPTVGestão/cadastros/views.py", line 594, in ImportarClientes
    dados_do_app.save()
  File "/mnt/c/Users/jreii/Desktop/IPTVGestão/cadastros/models.py", line 252, in save
    super(ContaDoAplicativo, self).save(*args, **kwargs)
  File "/mnt/c/Users/jreii/Desktop/IPTVGestão/.venv/lib/python3.10/site-packages/django/db/models/base.py", line 814, in save
    self.save_base(
  File "/mnt/c/Users/jreii/Desktop/IPTVGestão/.venv/lib/python3.10/site-packages/django/db/models/base.py", line 877, in save_base
    updated = self._save_table(
  File "/mnt/c/Users/jreii/Desktop/IPTVGestão/.venv/lib/python3.10/site-packages/django/db/models/base.py", line 1020, in _save_table
    results = self._do_insert(
  File "/mnt/c/Users/jreii/Desktop/IPTVGestão/.venv/lib/python3.10/site-packages/django/db/models/base.py", line 1061, in _do_insert
    return manager._insert(
  File "/mnt/c/Users/jreii/Desktop/IPTVGestão/.venv/lib/python3.10/site-packages/django/db/models/manager.py", line 87, in manager_method
    return getattr(self.get_queryset(), name)(*args, **kwargs)
  File "/mnt/c/Users/jreii/Desktop/IPTVGestão/.venv/lib/python3.10/site-packages/django/db/models/query.py", line 1805, in _insert
    return query.get_compiler(using=using).execute_sql(returning_fields)
  File "/mnt/c/Users/jreii/Desktop/IPTVGestão/.venv/lib/python3.10/site-packages/django/db/models/sql/compiler.py", line 1820, in execute_sql
    cursor.execute(sql, params)
  File "/mnt/c/Users/jreii/Desktop/IPTVGestão/.venv/lib/python3.10/site-packages/django/db/backends/utils.py", line 102, in execute
    return super().execute(sql, params)
  File "/mnt/c/Users/jreii/Desktop/IPTVGestão/.venv/lib/python3.10/site-packages/django/db/backends/utils.py", line 67, in execute
    return self._execute_with_wrappers(
  File "/mnt/c/Users/jreii/Desktop/IPTVGestão/.venv/lib/python3.10/site-packages/django/db/backends/utils.py", line 80, in _execute_with_wrappers
    return executor(sql, params, many, context)
  File "/mnt/c/Users/jreii/Desktop/IPTVGestão/.venv/lib/python3.10/site-packages/django/db/backends/utils.py", line 84, in _execute
    with self.db.wrap_database_errors:
  File "/mnt/c/Users/jreii/Desktop/IPTVGestão/.venv/lib/python3.10/site-packages/django/db/utils.py", line 91, in __exit__
    raise dj_exc_value.with_traceback(traceback) from exc_value
  File "/mnt/c/Users/jreii/Desktop/IPTVGestão/.venv/lib/python3.10/site-packages/django/db/backends/utils.py", line 89, in _execute
    return self.cursor.execute(sql, params)
  File "/mnt/c/Users/jreii/Desktop/IPTVGestão/.venv/lib/python3.10/site-packages/django/db/backends/sqlite3/base.py", line 328, in execute
    return super().execute(query, params)
django.db.utils.IntegrityError: NOT NULL constraint failed: cadastros_contadoaplicativo.app_id
[2023-05-19 13:35:04.642070-03:00][USER][admin] [IP][127.0.0.1] [ERRO][NOT NULL constraint failed: cadastros_contadoaplicativo.app_id]
Traceback (most recent call last):
  File "/mnt/c/Users/jreii/Desktop/IPTVGestão/.venv/lib/python3.10/site-packages/django/db/backends/utils.py", line 89, in _execute
    return self.cursor.execute(sql, params)
  File "/mnt/c/Users/jreii/Desktop/IPTVGestão/.venv/lib/python3.10/site-packages/django/db/backends/sqlite3/base.py", line 328, in execute
    return super().execute(query, params)
sqlite3.IntegrityError: NOT NULL constraint failed: cadastros_contadoaplicativo.app_id

The above exception was the direct cause of the following exception:

Traceback (most recent call last):
  File "/mnt/c/Users/jreii/Desktop/IPTVGestão/cadastros/views.py", line 594, in ImportarClientes
    dados_do_app.save()
  File "/mnt/c/Users/jreii/Desktop/IPTVGestão/cadastros/models.py", line 252, in save
    super(ContaDoAplicativo, self).save(*args, **kwargs)
  File "/mnt/c/Users/jreii/Desktop/IPTVGestão/.venv/lib/python3.10/site-packages/django/db/models/base.py", line 814, in save
    self.save_base(
  File "/mnt/c/Users/jreii/Desktop/IPTVGestão/.venv/lib/python3.10/site-packages/django/db/models/base.py", line 877, in save_base
    updated = self._save_table(
  File "/mnt/c/Users/jreii/Desktop/IPTVGestão/.venv/lib/python3.10/site-packages/django/db/models/base.py", line 1020, in _save_table
    results = self._do_insert(
  File "/mnt/c/Users/jreii/Desktop/IPTVGestão/.venv/lib/python3.10/site-packages/django/db/models/base.py", line 1061, in _do_insert
    return manager._insert(
  File "/mnt/c/Users/jreii/Desktop/IPTVGestão/.venv/lib/python3.10/site-packages/django/db/models/manager.py", line 87, in manager_method
    return getattr(self.get_queryset(), name)(*args, **kwargs)
  File "/mnt/c/Users/jreii/Desktop/IPTVGestão/.venv/lib/python3.10/site-packages/django/db/models/query.py", line 1805, in _insert
    return query.get_compiler(using=using).execute_sql(returning_fields)
  File "/mnt/c/Users/jreii/Desktop/IPTVGestão/.venv/lib/python3.10/site-packages/django/db/models/sql/compiler.py", line 1820, in execute_sql
    cursor.execute(sql, params)
  File "/mnt/c/Users/jreii/Desktop/IPTVGestão/.venv/lib/python3.10/site-packages/django/db/backends/utils.py", line 102, in execute
    return super().execute(sql, params)
  File "/mnt/c/Users/jreii/Desktop/IPTVGestão/.venv/lib/python3.10/site-packages/django/db/backends/utils.py", line 67, in execute
    return self._execute_with_wrappers(
  File "/mnt/c/Users/jreii/Desktop/IPTVGestão/.venv/lib/python3.10/site-packages/django/db/backends/utils.py", line 80, in _execute_with_wrappers
    return executor(sql, params, many, context)
  File "/mnt/c/Users/jreii/Desktop/IPTVGestão/.venv/lib/python3.10/site-packages/django/db/backends/utils.py", line 84, in _execute
    with self.db.wrap_database_errors:
  File "/mnt/c/Users/jreii/Desktop/IPTVGestão/.venv/lib/python3.10/site-packages/django/db/utils.py", line 91, in __exit__
    raise dj_exc_value.with_traceback(traceback) from exc_value
  File "/mnt/c/Users/jreii/Desktop/IPTVGestão/.venv/lib/python3.10/site-packages/django/db/backends/utils.py", line 89, in _execute
    return self.cursor.execute(sql, params)
  File "/mnt/c/Users/jreii/Desktop/IPTVGestão/.venv/lib/python3.10/site-packages/django/db/backends/sqlite3/base.py", line 328, in execute
    return super().execute(query, params)
django.db.utils.IntegrityError: NOT NULL constraint failed: cadastros_contadoaplicativo.app_id
[2023-05-19 13:35:04.664017-03:00][USER][admin] [IP][127.0.0.1] [ERRO][NOT NULL constraint failed: cadastros_contadoaplicativo.app_id]
Traceback (most recent call last):
  File "/mnt/c/Users/jreii/Desktop/IPTVGestão/.venv/lib/python3.10/site-packages/django/db/backends/utils.py", line 89, in _execute
    return self.cursor.execute(sql, params)
  File "/mnt/c/Users/jreii/Desktop/IPTVGestão/.venv/lib/python3.10/site-packages/django/db/backends/sqlite3/base.py", line 328, in execute
    return super().execute(query, params)
sqlite3.IntegrityError: NOT NULL constraint failed: cadastros_contadoaplicativo.app_id

The above exception was the direct cause of the following exception:

Traceback (most recent call last):
  File "/mnt/c/Users/jreii/Desktop/IPTVGestão/cadastros/views.py", line 594, in ImportarClientes
    dados_do_app.save()
  File "/mnt/c/Users/jreii/Desktop/IPTVGestão/cadastros/models.py", line 252, in save
    super(ContaDoAplicativo, self).save(*args, **kwargs)
  File "/mnt/c/Users/jreii/Desktop/IPTVGestão/.venv/lib/python3.10/site-packages/django/db/models/base.py", line 814, in save
    self.save_base(
  File "/mnt/c/Users/jreii/Desktop/IPTVGestão/.venv/lib/python3.10/site-packages/django/db/models/base.py", line 877, in save_base
    updated = self._save_table(
  File "/mnt/c/Users/jreii/Desktop/IPTVGestão/.venv/lib/python3.10/site-packages/django/db/models/base.py", line 1020, in _save_table
    results = self._do_insert(
  File "/mnt/c/Users/jreii/Desktop/IPTVGestão/.venv/lib/python3.10/site-packages/django/db/models/base.py", line 1061, in _do_insert
    return manager._insert(
  File "/mnt/c/Users/jreii/Desktop/IPTVGestão/.venv/lib/python3.10/site-packages/django/db/models/manager.py", line 87, in manager_method
    return getattr(self.get_queryset(), name)(*args, **kwargs)
  File "/mnt/c/Users/jreii/Desktop/IPTVGestão/.venv/lib/python3.10/site-packages/django/db/models/query.py", line 1805, in _insert
    return query.get_compiler(using=using).execute_sql(returning_fields)
  File "/mnt/c/Users/jreii/Desktop/IPTVGestão/.venv/lib/python3.10/site-packages/django/db/models/sql/compiler.py", line 1820, in execute_sql
    cursor.execute(sql, params)
  File "/mnt/c/Users/jreii/Desktop/IPTVGestão/.venv/lib/python3.10/site-packages/django/db/backends/utils.py", line 102, in execute
    return super().execute(sql, params)
  File "/mnt/c/Users/jreii/Desktop/IPTVGestão/.venv/lib/python3.10/site-packages/django/db/backends/utils.py", line 67, in execute
    return self._execute_with_wrappers(
  File "/mnt/c/Users/jreii/Desktop/IPTVGestão/.venv/lib/python3.10/site-packages/django/db/backends/utils.py", line 80, in _execute_with_wrappers
    return executor(sql, params, many, context)
  File "/mnt/c/Users/jreii/Desktop/IPTVGestão/.venv/lib/python3.10/site-packages/django/db/backends/utils.py", line 84, in _execute
    with self.db.wrap_database_errors:
  File "/mnt/c/Users/jreii/Desktop/IPTVGestão/.venv/lib/python3.10/site-packages/django/db/utils.py", line 91, in __exit__
    raise dj_exc_value.with_traceback(traceback) from exc_value
  File "/mnt/c/Users/jreii/Desktop/IPTVGestão/.venv/lib/python3.10/site-packages/django/db/backends/utils.py", line 89, in _execute
    return self.cursor.execute(sql, params)
  File "/mnt/c/Users/jreii/Desktop/IPTVGestão/.venv/lib/python3.10/site-packages/django/db/backends/sqlite3/base.py", line 328, in execute
    return super().execute(query, params)
django.db.utils.IntegrityError: NOT NULL constraint failed: cadastros_contadoaplicativo.app_id
[2023-05-19 14:05:47.562939-03:00][USER][admin] [IP][127.0.0.1] [ERRO][NOT NULL constraint failed: cadastros_contadoaplicativo.app_id]
Traceback (most recent call last):
  File "/mnt/c/Users/jreii/Desktop/IPTVGestão/.venv/lib/python3.10/site-packages/django/db/backends/utils.py", line 89, in _execute
    return self.cursor.execute(sql, params)
  File "/mnt/c/Users/jreii/Desktop/IPTVGestão/.venv/lib/python3.10/site-packages/django/db/backends/sqlite3/base.py", line 328, in execute
    return super().execute(query, params)
sqlite3.IntegrityError: NOT NULL constraint failed: cadastros_contadoaplicativo.app_id

The above exception was the direct cause of the following exception:

Traceback (most recent call last):
  File "/mnt/c/Users/jreii/Desktop/IPTVGestão/cadastros/views.py", line 594, in ImportarClientes
    dados_do_app.save()
  File "/mnt/c/Users/jreii/Desktop/IPTVGestão/cadastros/models.py", line 252, in save
    super(ContaDoAplicativo, self).save(*args, **kwargs)
  File "/mnt/c/Users/jreii/Desktop/IPTVGestão/.venv/lib/python3.10/site-packages/django/db/models/base.py", line 814, in save
    self.save_base(
  File "/mnt/c/Users/jreii/Desktop/IPTVGestão/.venv/lib/python3.10/site-packages/django/db/models/base.py", line 877, in save_base
    updated = self._save_table(
  File "/mnt/c/Users/jreii/Desktop/IPTVGestão/.venv/lib/python3.10/site-packages/django/db/models/base.py", line 1020, in _save_table
    results = self._do_insert(
  File "/mnt/c/Users/jreii/Desktop/IPTVGestão/.venv/lib/python3.10/site-packages/django/db/models/base.py", line 1061, in _do_insert
    return manager._insert(
  File "/mnt/c/Users/jreii/Desktop/IPTVGestão/.venv/lib/python3.10/site-packages/django/db/models/manager.py", line 87, in manager_method
    return getattr(self.get_queryset(), name)(*args, **kwargs)
  File "/mnt/c/Users/jreii/Desktop/IPTVGestão/.venv/lib/python3.10/site-packages/django/db/models/query.py", line 1805, in _insert
    return query.get_compiler(using=using).execute_sql(returning_fields)
  File "/mnt/c/Users/jreii/Desktop/IPTVGestão/.venv/lib/python3.10/site-packages/django/db/models/sql/compiler.py", line 1820, in execute_sql
    cursor.execute(sql, params)
  File "/mnt/c/Users/jreii/Desktop/IPTVGestão/.venv/lib/python3.10/site-packages/django/db/backends/utils.py", line 102, in execute
    return super().execute(sql, params)
  File "/mnt/c/Users/jreii/Desktop/IPTVGestão/.venv/lib/python3.10/site-packages/django/db/backends/utils.py", line 67, in execute
    return self._execute_with_wrappers(
  File "/mnt/c/Users/jreii/Desktop/IPTVGestão/.venv/lib/python3.10/site-packages/django/db/backends/utils.py", line 80, in _execute_with_wrappers
    return executor(sql, params, many, context)
  File "/mnt/c/Users/jreii/Desktop/IPTVGestão/.venv/lib/python3.10/site-packages/django/db/backends/utils.py", line 84, in _execute
    with self.db.wrap_database_errors:
  File "/mnt/c/Users/jreii/Desktop/IPTVGestão/.venv/lib/python3.10/site-packages/django/db/utils.py", line 91, in __exit__
    raise dj_exc_value.with_traceback(traceback) from exc_value
  File "/mnt/c/Users/jreii/Desktop/IPTVGestão/.venv/lib/python3.10/site-packages/django/db/backends/utils.py", line 89, in _execute
    return self.cursor.execute(sql, params)
  File "/mnt/c/Users/jreii/Desktop/IPTVGestão/.venv/lib/python3.10/site-packages/django/db/backends/sqlite3/base.py", line 328, in execute
    return super().execute(query, params)
django.db.utils.IntegrityError: NOT NULL constraint failed: cadastros_contadoaplicativo.app_id
[2023-05-19 14:05:47.585557-03:00][USER][admin] [IP][127.0.0.1] [ERRO][NOT NULL constraint failed: cadastros_contadoaplicativo.app_id]
Traceback (most recent call last):
  File "/mnt/c/Users/jreii/Desktop/IPTVGestão/.venv/lib/python3.10/site-packages/django/db/backends/utils.py", line 89, in _execute
    return self.cursor.execute(sql, params)
  File "/mnt/c/Users/jreii/Desktop/IPTVGestão/.venv/lib/python3.10/site-packages/django/db/backends/sqlite3/base.py", line 328, in execute
    return super().execute(query, params)
sqlite3.IntegrityError: NOT NULL constraint failed: cadastros_contadoaplicativo.app_id

The above exception was the direct cause of the following exception:

Traceback (most recent call last):
  File "/mnt/c/Users/jreii/Desktop/IPTVGestão/cadastros/views.py", line 594, in ImportarClientes
    dados_do_app.save()
  File "/mnt/c/Users/jreii/Desktop/IPTVGestão/cadastros/models.py", line 252, in save
    super(ContaDoAplicativo, self).save(*args, **kwargs)
  File "/mnt/c/Users/jreii/Desktop/IPTVGestão/.venv/lib/python3.10/site-packages/django/db/models/base.py", line 814, in save
    self.save_base(
  File "/mnt/c/Users/jreii/Desktop/IPTVGestão/.venv/lib/python3.10/site-packages/django/db/models/base.py", line 877, in save_base
    updated = self._save_table(
  File "/mnt/c/Users/jreii/Desktop/IPTVGestão/.venv/lib/python3.10/site-packages/django/db/models/base.py", line 1020, in _save_table
    results = self._do_insert(
  File "/mnt/c/Users/jreii/Desktop/IPTVGestão/.venv/lib/python3.10/site-packages/django/db/models/base.py", line 1061, in _do_insert
    return manager._insert(
  File "/mnt/c/Users/jreii/Desktop/IPTVGestão/.venv/lib/python3.10/site-packages/django/db/models/manager.py", line 87, in manager_method
    return getattr(self.get_queryset(), name)(*args, **kwargs)
  File "/mnt/c/Users/jreii/Desktop/IPTVGestão/.venv/lib/python3.10/site-packages/django/db/models/query.py", line 1805, in _insert
    return query.get_compiler(using=using).execute_sql(returning_fields)
  File "/mnt/c/Users/jreii/Desktop/IPTVGestão/.venv/lib/python3.10/site-packages/django/db/models/sql/compiler.py", line 1820, in execute_sql
    cursor.execute(sql, params)
  File "/mnt/c/Users/jreii/Desktop/IPTVGestão/.venv/lib/python3.10/site-packages/django/db/backends/utils.py", line 102, in execute
    return super().execute(sql, params)
  File "/mnt/c/Users/jreii/Desktop/IPTVGestão/.venv/lib/python3.10/site-packages/django/db/backends/utils.py", line 67, in execute
    return self._execute_with_wrappers(
  File "/mnt/c/Users/jreii/Desktop/IPTVGestão/.venv/lib/python3.10/site-packages/django/db/backends/utils.py", line 80, in _execute_with_wrappers
    return executor(sql, params, many, context)
  File "/mnt/c/Users/jreii/Desktop/IPTVGestão/.venv/lib/python3.10/site-packages/django/db/backends/utils.py", line 84, in _execute
    with self.db.wrap_database_errors:
  File "/mnt/c/Users/jreii/Desktop/IPTVGestão/.venv/lib/python3.10/site-packages/django/db/utils.py", line 91, in __exit__
    raise dj_exc_value.with_traceback(traceback) from exc_value
  File "/mnt/c/Users/jreii/Desktop/IPTVGestão/.venv/lib/python3.10/site-packages/django/db/backends/utils.py", line 89, in _execute
    return self.cursor.execute(sql, params)
  File "/mnt/c/Users/jreii/Desktop/IPTVGestão/.venv/lib/python3.10/site-packages/django/db/backends/sqlite3/base.py", line 328, in execute
    return super().execute(query, params)
django.db.utils.IntegrityError: NOT NULL constraint failed: cadastros_contadoaplicativo.app_id
[2023-05-19 14:05:47.625762-03:00][USER][admin] [IP][127.0.0.1] [ERRO][NOT NULL constraint failed: cadastros_contadoaplicativo.app_id]
Traceback (most recent call last):
  File "/mnt/c/Users/jreii/Desktop/IPTVGestão/.venv/lib/python3.10/site-packages/django/db/backends/utils.py", line 89, in _execute
    return self.cursor.execute(sql, params)
  File "/mnt/c/Users/jreii/Desktop/IPTVGestão/.venv/lib/python3.10/site-packages/django/db/backends/sqlite3/base.py", line 328, in execute
    return super().execute(query, params)
sqlite3.IntegrityError: NOT NULL constraint failed: cadastros_contadoaplicativo.app_id

The above exception was the direct cause of the following exception:

Traceback (most recent call last):
  File "/mnt/c/Users/jreii/Desktop/IPTVGestão/cadastros/views.py", line 594, in ImportarClientes
    dados_do_app.save()
  File "/mnt/c/Users/jreii/Desktop/IPTVGestão/cadastros/models.py", line 252, in save
    super(ContaDoAplicativo, self).save(*args, **kwargs)
  File "/mnt/c/Users/jreii/Desktop/IPTVGestão/.venv/lib/python3.10/site-packages/django/db/models/base.py", line 814, in save
    self.save_base(
  File "/mnt/c/Users/jreii/Desktop/IPTVGestão/.venv/lib/python3.10/site-packages/django/db/models/base.py", line 877, in save_base
    updated = self._save_table(
  File "/mnt/c/Users/jreii/Desktop/IPTVGestão/.venv/lib/python3.10/site-packages/django/db/models/base.py", line 1020, in _save_table
    results = self._do_insert(
  File "/mnt/c/Users/jreii/Desktop/IPTVGestão/.venv/lib/python3.10/site-packages/django/db/models/base.py", line 1061, in _do_insert
    return manager._insert(
  File "/mnt/c/Users/jreii/Desktop/IPTVGestão/.venv/lib/python3.10/site-packages/django/db/models/manager.py", line 87, in manager_method
    return getattr(self.get_queryset(), name)(*args, **kwargs)
  File "/mnt/c/Users/jreii/Desktop/IPTVGestão/.venv/lib/python3.10/site-packages/django/db/models/query.py", line 1805, in _insert
    return query.get_compiler(using=using).execute_sql(returning_fields)
  File "/mnt/c/Users/jreii/Desktop/IPTVGestão/.venv/lib/python3.10/site-packages/django/db/models/sql/compiler.py", line 1820, in execute_sql
    cursor.execute(sql, params)
  File "/mnt/c/Users/jreii/Desktop/IPTVGestão/.venv/lib/python3.10/site-packages/django/db/backends/utils.py", line 102, in execute
    return super().execute(sql, params)
  File "/mnt/c/Users/jreii/Desktop/IPTVGestão/.venv/lib/python3.10/site-packages/django/db/backends/utils.py", line 67, in execute
    return self._execute_with_wrappers(
  File "/mnt/c/Users/jreii/Desktop/IPTVGestão/.venv/lib/python3.10/site-packages/django/db/backends/utils.py", line 80, in _execute_with_wrappers
    return executor(sql, params, many, context)
  File "/mnt/c/Users/jreii/Desktop/IPTVGestão/.venv/lib/python3.10/site-packages/django/db/backends/utils.py", line 84, in _execute
    with self.db.wrap_database_errors:
  File "/mnt/c/Users/jreii/Desktop/IPTVGestão/.venv/lib/python3.10/site-packages/django/db/utils.py", line 91, in __exit__
    raise dj_exc_value.with_traceback(traceback) from exc_value
  File "/mnt/c/Users/jreii/Desktop/IPTVGestão/.venv/lib/python3.10/site-packages/django/db/backends/utils.py", line 89, in _execute
    return self.cursor.execute(sql, params)
  File "/mnt/c/Users/jreii/Desktop/IPTVGestão/.venv/lib/python3.10/site-packages/django/db/backends/sqlite3/base.py", line 328, in execute
    return super().execute(query, params)
django.db.utils.IntegrityError: NOT NULL constraint failed: cadastros_contadoaplicativo.app_id
[2023-05-19 14:05:47.634004-03:00][USER][admin] [IP][127.0.0.1] [ERRO][NOT NULL constraint failed: cadastros_contadoaplicativo.app_id]
Traceback (most recent call last):
  File "/mnt/c/Users/jreii/Desktop/IPTVGestão/.venv/lib/python3.10/site-packages/django/db/backends/utils.py", line 89, in _execute
    return self.cursor.execute(sql, params)
  File "/mnt/c/Users/jreii/Desktop/IPTVGestão/.venv/lib/python3.10/site-packages/django/db/backends/sqlite3/base.py", line 328, in execute
    return super().execute(query, params)
sqlite3.IntegrityError: NOT NULL constraint failed: cadastros_contadoaplicativo.app_id

The above exception was the direct cause of the following exception:

Traceback (most recent call last):
  File "/mnt/c/Users/jreii/Desktop/IPTVGestão/cadastros/views.py", line 594, in ImportarClientes
    dados_do_app.save()
  File "/mnt/c/Users/jreii/Desktop/IPTVGestão/cadastros/models.py", line 252, in save
    super(ContaDoAplicativo, self).save(*args, **kwargs)
  File "/mnt/c/Users/jreii/Desktop/IPTVGestão/.venv/lib/python3.10/site-packages/django/db/models/base.py", line 814, in save
    self.save_base(
  File "/mnt/c/Users/jreii/Desktop/IPTVGestão/.venv/lib/python3.10/site-packages/django/db/models/base.py", line 877, in save_base
    updated = self._save_table(
  File "/mnt/c/Users/jreii/Desktop/IPTVGestão/.venv/lib/python3.10/site-packages/django/db/models/base.py", line 1020, in _save_table
    results = self._do_insert(
  File "/mnt/c/Users/jreii/Desktop/IPTVGestão/.venv/lib/python3.10/site-packages/django/db/models/base.py", line 1061, in _do_insert
    return manager._insert(
  File "/mnt/c/Users/jreii/Desktop/IPTVGestão/.venv/lib/python3.10/site-packages/django/db/models/manager.py", line 87, in manager_method
    return getattr(self.get_queryset(), name)(*args, **kwargs)
  File "/mnt/c/Users/jreii/Desktop/IPTVGestão/.venv/lib/python3.10/site-packages/django/db/models/query.py", line 1805, in _insert
    return query.get_compiler(using=using).execute_sql(returning_fields)
  File "/mnt/c/Users/jreii/Desktop/IPTVGestão/.venv/lib/python3.10/site-packages/django/db/models/sql/compiler.py", line 1820, in execute_sql
    cursor.execute(sql, params)
  File "/mnt/c/Users/jreii/Desktop/IPTVGestão/.venv/lib/python3.10/site-packages/django/db/backends/utils.py", line 102, in execute
    return super().execute(sql, params)
  File "/mnt/c/Users/jreii/Desktop/IPTVGestão/.venv/lib/python3.10/site-packages/django/db/backends/utils.py", line 67, in execute
    return self._execute_with_wrappers(
  File "/mnt/c/Users/jreii/Desktop/IPTVGestão/.venv/lib/python3.10/site-packages/django/db/backends/utils.py", line 80, in _execute_with_wrappers
    return executor(sql, params, many, context)
  File "/mnt/c/Users/jreii/Desktop/IPTVGestão/.venv/lib/python3.10/site-packages/django/db/backends/utils.py", line 84, in _execute
    with self.db.wrap_database_errors:
  File "/mnt/c/Users/jreii/Desktop/IPTVGestão/.venv/lib/python3.10/site-packages/django/db/utils.py", line 91, in __exit__
    raise dj_exc_value.with_traceback(traceback) from exc_value
  File "/mnt/c/Users/jreii/Desktop/IPTVGestão/.venv/lib/python3.10/site-packages/django/db/backends/utils.py", line 89, in _execute
    return self.cursor.execute(sql, params)
  File "/mnt/c/Users/jreii/Desktop/IPTVGestão/.venv/lib/python3.10/site-packages/django/db/backends/sqlite3/base.py", line 328, in execute
    return super().execute(query, params)
django.db.utils.IntegrityError: NOT NULL constraint failed: cadastros_contadoaplicativo.app_id
[2023-05-19 14:05:47.712977-03:00][USER][admin] [IP][127.0.0.1] [ERRO][NOT NULL constraint failed: cadastros_contadoaplicativo.app_id]
Traceback (most recent call last):
  File "/mnt/c/Users/jreii/Desktop/IPTVGestão/.venv/lib/python3.10/site-packages/django/db/backends/utils.py", line 89, in _execute
    return self.cursor.execute(sql, params)
  File "/mnt/c/Users/jreii/Desktop/IPTVGestão/.venv/lib/python3.10/site-packages/django/db/backends/sqlite3/base.py", line 328, in execute
    return super().execute(query, params)
sqlite3.IntegrityError: NOT NULL constraint failed: cadastros_contadoaplicativo.app_id

The above exception was the direct cause of the following exception:

Traceback (most recent call last):
  File "/mnt/c/Users/jreii/Desktop/IPTVGestão/cadastros/views.py", line 594, in ImportarClientes
    dados_do_app.save()
  File "/mnt/c/Users/jreii/Desktop/IPTVGestão/cadastros/models.py", line 252, in save
    super(ContaDoAplicativo, self).save(*args, **kwargs)
  File "/mnt/c/Users/jreii/Desktop/IPTVGestão/.venv/lib/python3.10/site-packages/django/db/models/base.py", line 814, in save
    self.save_base(
  File "/mnt/c/Users/jreii/Desktop/IPTVGestão/.venv/lib/python3.10/site-packages/django/db/models/base.py", line 877, in save_base
    updated = self._save_table(
  File "/mnt/c/Users/jreii/Desktop/IPTVGestão/.venv/lib/python3.10/site-packages/django/db/models/base.py", line 1020, in _save_table
    results = self._do_insert(
  File "/mnt/c/Users/jreii/Desktop/IPTVGestão/.venv/lib/python3.10/site-packages/django/db/models/base.py", line 1061, in _do_insert
    return manager._insert(
  File "/mnt/c/Users/jreii/Desktop/IPTVGestão/.venv/lib/python3.10/site-packages/django/db/models/manager.py", line 87, in manager_method
    return getattr(self.get_queryset(), name)(*args, **kwargs)
  File "/mnt/c/Users/jreii/Desktop/IPTVGestão/.venv/lib/python3.10/site-packages/django/db/models/query.py", line 1805, in _insert
    return query.get_compiler(using=using).execute_sql(returning_fields)
  File "/mnt/c/Users/jreii/Desktop/IPTVGestão/.venv/lib/python3.10/site-packages/django/db/models/sql/compiler.py", line 1820, in execute_sql
    cursor.execute(sql, params)
  File "/mnt/c/Users/jreii/Desktop/IPTVGestão/.venv/lib/python3.10/site-packages/django/db/backends/utils.py", line 102, in execute
    return super().execute(sql, params)
  File "/mnt/c/Users/jreii/Desktop/IPTVGestão/.venv/lib/python3.10/site-packages/django/db/backends/utils.py", line 67, in execute
    return self._execute_with_wrappers(
  File "/mnt/c/Users/jreii/Desktop/IPTVGestão/.venv/lib/python3.10/site-packages/django/db/backends/utils.py", line 80, in _execute_with_wrappers
    return executor(sql, params, many, context)
  File "/mnt/c/Users/jreii/Desktop/IPTVGestão/.venv/lib/python3.10/site-packages/django/db/backends/utils.py", line 84, in _execute
    with self.db.wrap_database_errors:
  File "/mnt/c/Users/jreii/Desktop/IPTVGestão/.venv/lib/python3.10/site-packages/django/db/utils.py", line 91, in __exit__
    raise dj_exc_value.with_traceback(traceback) from exc_value
  File "/mnt/c/Users/jreii/Desktop/IPTVGestão/.venv/lib/python3.10/site-packages/django/db/backends/utils.py", line 89, in _execute
    return self.cursor.execute(sql, params)
  File "/mnt/c/Users/jreii/Desktop/IPTVGestão/.venv/lib/python3.10/site-packages/django/db/backends/sqlite3/base.py", line 328, in execute
    return super().execute(query, params)
django.db.utils.IntegrityError: NOT NULL constraint failed: cadastros_contadoaplicativo.app_id
[2023-05-19 14:05:47.720843-03:00][USER][admin] [IP][127.0.0.1] [ERRO][NOT NULL constraint failed: cadastros_contadoaplicativo.app_id]
Traceback (most recent call last):
  File "/mnt/c/Users/jreii/Desktop/IPTVGestão/.venv/lib/python3.10/site-packages/django/db/backends/utils.py", line 89, in _execute
    return self.cursor.execute(sql, params)
  File "/mnt/c/Users/jreii/Desktop/IPTVGestão/.venv/lib/python3.10/site-packages/django/db/backends/sqlite3/base.py", line 328, in execute
    return super().execute(query, params)
sqlite3.IntegrityError: NOT NULL constraint failed: cadastros_contadoaplicativo.app_id

The above exception was the direct cause of the following exception:

Traceback (most recent call last):
  File "/mnt/c/Users/jreii/Desktop/IPTVGestão/cadastros/views.py", line 594, in ImportarClientes
    dados_do_app.save()
  File "/mnt/c/Users/jreii/Desktop/IPTVGestão/cadastros/models.py", line 252, in save
    super(ContaDoAplicativo, self).save(*args, **kwargs)
  File "/mnt/c/Users/jreii/Desktop/IPTVGestão/.venv/lib/python3.10/site-packages/django/db/models/base.py", line 814, in save
    self.save_base(
  File "/mnt/c/Users/jreii/Desktop/IPTVGestão/.venv/lib/python3.10/site-packages/django/db/models/base.py", line 877, in save_base
    updated = self._save_table(
  File "/mnt/c/Users/jreii/Desktop/IPTVGestão/.venv/lib/python3.10/site-packages/django/db/models/base.py", line 1020, in _save_table
    results = self._do_insert(
  File "/mnt/c/Users/jreii/Desktop/IPTVGestão/.venv/lib/python3.10/site-packages/django/db/models/base.py", line 1061, in _do_insert
    return manager._insert(
  File "/mnt/c/Users/jreii/Desktop/IPTVGestão/.venv/lib/python3.10/site-packages/django/db/models/manager.py", line 87, in manager_method
    return getattr(self.get_queryset(), name)(*args, **kwargs)
  File "/mnt/c/Users/jreii/Desktop/IPTVGestão/.venv/lib/python3.10/site-packages/django/db/models/query.py", line 1805, in _insert
    return query.get_compiler(using=using).execute_sql(returning_fields)
  File "/mnt/c/Users/jreii/Desktop/IPTVGestão/.venv/lib/python3.10/site-packages/django/db/models/sql/compiler.py", line 1820, in execute_sql
    cursor.execute(sql, params)
  File "/mnt/c/Users/jreii/Desktop/IPTVGestão/.venv/lib/python3.10/site-packages/django/db/backends/utils.py", line 102, in execute
    return super().execute(sql, params)
  File "/mnt/c/Users/jreii/Desktop/IPTVGestão/.venv/lib/python3.10/site-packages/django/db/backends/utils.py", line 67, in execute
    return self._execute_with_wrappers(
  File "/mnt/c/Users/jreii/Desktop/IPTVGestão/.venv/lib/python3.10/site-packages/django/db/backends/utils.py", line 80, in _execute_with_wrappers
    return executor(sql, params, many, context)
  File "/mnt/c/Users/jreii/Desktop/IPTVGestão/.venv/lib/python3.10/site-packages/django/db/backends/utils.py", line 84, in _execute
    with self.db.wrap_database_errors:
  File "/mnt/c/Users/jreii/Desktop/IPTVGestão/.venv/lib/python3.10/site-packages/django/db/utils.py", line 91, in __exit__
    raise dj_exc_value.with_traceback(traceback) from exc_value
  File "/mnt/c/Users/jreii/Desktop/IPTVGestão/.venv/lib/python3.10/site-packages/django/db/backends/utils.py", line 89, in _execute
    return self.cursor.execute(sql, params)
  File "/mnt/c/Users/jreii/Desktop/IPTVGestão/.venv/lib/python3.10/site-packages/django/db/backends/sqlite3/base.py", line 328, in execute
    return super().execute(query, params)
django.db.utils.IntegrityError: NOT NULL constraint failed: cadastros_contadoaplicativo.app_id
[2023-05-19 14:05:47.730460-03:00][USER][admin] [IP][127.0.0.1] [ERRO][NOT NULL constraint failed: cadastros_contadoaplicativo.app_id]
Traceback (most recent call last):
  File "/mnt/c/Users/jreii/Desktop/IPTVGestão/.venv/lib/python3.10/site-packages/django/db/backends/utils.py", line 89, in _execute
    return self.cursor.execute(sql, params)
  File "/mnt/c/Users/jreii/Desktop/IPTVGestão/.venv/lib/python3.10/site-packages/django/db/backends/sqlite3/base.py", line 328, in execute
    return super().execute(query, params)
sqlite3.IntegrityError: NOT NULL constraint failed: cadastros_contadoaplicativo.app_id

The above exception was the direct cause of the following exception:

Traceback (most recent call last):
  File "/mnt/c/Users/jreii/Desktop/IPTVGestão/cadastros/views.py", line 594, in ImportarClientes
    dados_do_app.save()
  File "/mnt/c/Users/jreii/Desktop/IPTVGestão/cadastros/models.py", line 252, in save
    super(ContaDoAplicativo, self).save(*args, **kwargs)
  File "/mnt/c/Users/jreii/Desktop/IPTVGestão/.venv/lib/python3.10/site-packages/django/db/models/base.py", line 814, in save
    self.save_base(
  File "/mnt/c/Users/jreii/Desktop/IPTVGestão/.venv/lib/python3.10/site-packages/django/db/models/base.py", line 877, in save_base
    updated = self._save_table(
  File "/mnt/c/Users/jreii/Desktop/IPTVGestão/.venv/lib/python3.10/site-packages/django/db/models/base.py", line 1020, in _save_table
    results = self._do_insert(
  File "/mnt/c/Users/jreii/Desktop/IPTVGestão/.venv/lib/python3.10/site-packages/django/db/models/base.py", line 1061, in _do_insert
    return manager._insert(
  File "/mnt/c/Users/jreii/Desktop/IPTVGestão/.venv/lib/python3.10/site-packages/django/db/models/manager.py", line 87, in manager_method
    return getattr(self.get_queryset(), name)(*args, **kwargs)
  File "/mnt/c/Users/jreii/Desktop/IPTVGestão/.venv/lib/python3.10/site-packages/django/db/models/query.py", line 1805, in _insert
    return query.get_compiler(using=using).execute_sql(returning_fields)
  File "/mnt/c/Users/jreii/Desktop/IPTVGestão/.venv/lib/python3.10/site-packages/django/db/models/sql/compiler.py", line 1820, in execute_sql
    cursor.execute(sql, params)
  File "/mnt/c/Users/jreii/Desktop/IPTVGestão/.venv/lib/python3.10/site-packages/django/db/backends/utils.py", line 102, in execute
    return super().execute(sql, params)
  File "/mnt/c/Users/jreii/Desktop/IPTVGestão/.venv/lib/python3.10/site-packages/django/db/backends/utils.py", line 67, in execute
    return self._execute_with_wrappers(
  File "/mnt/c/Users/jreii/Desktop/IPTVGestão/.venv/lib/python3.10/site-packages/django/db/backends/utils.py", line 80, in _execute_with_wrappers
    return executor(sql, params, many, context)
  File "/mnt/c/Users/jreii/Desktop/IPTVGestão/.venv/lib/python3.10/site-packages/django/db/backends/utils.py", line 84, in _execute
    with self.db.wrap_database_errors:
  File "/mnt/c/Users/jreii/Desktop/IPTVGestão/.venv/lib/python3.10/site-packages/django/db/utils.py", line 91, in __exit__
    raise dj_exc_value.with_traceback(traceback) from exc_value
  File "/mnt/c/Users/jreii/Desktop/IPTVGestão/.venv/lib/python3.10/site-packages/django/db/backends/utils.py", line 89, in _execute
    return self.cursor.execute(sql, params)
  File "/mnt/c/Users/jreii/Desktop/IPTVGestão/.venv/lib/python3.10/site-packages/django/db/backends/sqlite3/base.py", line 328, in execute
    return super().execute(query, params)
django.db.utils.IntegrityError: NOT NULL constraint failed: cadastros_contadoaplicativo.app_id
[2023-05-19 14:06:37.221550-03:00][USER][admin] [IP][127.0.0.1] [ERRO][NOT NULL constraint failed: cadastros_contadoaplicativo.app_id]
Traceback (most recent call last):
  File "/mnt/c/Users/jreii/Desktop/IPTVGestão/.venv/lib/python3.10/site-packages/django/db/backends/utils.py", line 89, in _execute
    return self.cursor.execute(sql, params)
  File "/mnt/c/Users/jreii/Desktop/IPTVGestão/.venv/lib/python3.10/site-packages/django/db/backends/sqlite3/base.py", line 328, in execute
    return super().execute(query, params)
sqlite3.IntegrityError: NOT NULL constraint failed: cadastros_contadoaplicativo.app_id

The above exception was the direct cause of the following exception:

Traceback (most recent call last):
  File "/mnt/c/Users/jreii/Desktop/IPTVGestão/cadastros/views.py", line 595, in ImportarClientes
    dados_do_app.save()
  File "/mnt/c/Users/jreii/Desktop/IPTVGestão/cadastros/models.py", line 252, in save
    super(ContaDoAplicativo, self).save(*args, **kwargs)
  File "/mnt/c/Users/jreii/Desktop/IPTVGestão/.venv/lib/python3.10/site-packages/django/db/models/base.py", line 814, in save
    self.save_base(
  File "/mnt/c/Users/jreii/Desktop/IPTVGestão/.venv/lib/python3.10/site-packages/django/db/models/base.py", line 877, in save_base
    updated = self._save_table(
  File "/mnt/c/Users/jreii/Desktop/IPTVGestão/.venv/lib/python3.10/site-packages/django/db/models/base.py", line 1020, in _save_table
    results = self._do_insert(
  File "/mnt/c/Users/jreii/Desktop/IPTVGestão/.venv/lib/python3.10/site-packages/django/db/models/base.py", line 1061, in _do_insert
    return manager._insert(
  File "/mnt/c/Users/jreii/Desktop/IPTVGestão/.venv/lib/python3.10/site-packages/django/db/models/manager.py", line 87, in manager_method
    return getattr(self.get_queryset(), name)(*args, **kwargs)
  File "/mnt/c/Users/jreii/Desktop/IPTVGestão/.venv/lib/python3.10/site-packages/django/db/models/query.py", line 1805, in _insert
    return query.get_compiler(using=using).execute_sql(returning_fields)
  File "/mnt/c/Users/jreii/Desktop/IPTVGestão/.venv/lib/python3.10/site-packages/django/db/models/sql/compiler.py", line 1820, in execute_sql
    cursor.execute(sql, params)
  File "/mnt/c/Users/jreii/Desktop/IPTVGestão/.venv/lib/python3.10/site-packages/django/db/backends/utils.py", line 102, in execute
    return super().execute(sql, params)
  File "/mnt/c/Users/jreii/Desktop/IPTVGestão/.venv/lib/python3.10/site-packages/django/db/backends/utils.py", line 67, in execute
    return self._execute_with_wrappers(
  File "/mnt/c/Users/jreii/Desktop/IPTVGestão/.venv/lib/python3.10/site-packages/django/db/backends/utils.py", line 80, in _execute_with_wrappers
    return executor(sql, params, many, context)
  File "/mnt/c/Users/jreii/Desktop/IPTVGestão/.venv/lib/python3.10/site-packages/django/db/backends/utils.py", line 84, in _execute
    with self.db.wrap_database_errors:
  File "/mnt/c/Users/jreii/Desktop/IPTVGestão/.venv/lib/python3.10/site-packages/django/db/utils.py", line 91, in __exit__
    raise dj_exc_value.with_traceback(traceback) from exc_value
  File "/mnt/c/Users/jreii/Desktop/IPTVGestão/.venv/lib/python3.10/site-packages/django/db/backends/utils.py", line 89, in _execute
    return self.cursor.execute(sql, params)
  File "/mnt/c/Users/jreii/Desktop/IPTVGestão/.venv/lib/python3.10/site-packages/django/db/backends/sqlite3/base.py", line 328, in execute
    return super().execute(query, params)
django.db.utils.IntegrityError: NOT NULL constraint failed: cadastros_contadoaplicativo.app_id
[2023-05-19 14:06:37.249120-03:00][USER][admin] [IP][127.0.0.1] [ERRO][NOT NULL constraint failed: cadastros_contadoaplicativo.app_id]
Traceback (most recent call last):
  File "/mnt/c/Users/jreii/Desktop/IPTVGestão/.venv/lib/python3.10/site-packages/django/db/backends/utils.py", line 89, in _execute
    return self.cursor.execute(sql, params)
  File "/mnt/c/Users/jreii/Desktop/IPTVGestão/.venv/lib/python3.10/site-packages/django/db/backends/sqlite3/base.py", line 328, in execute
    return super().execute(query, params)
sqlite3.IntegrityError: NOT NULL constraint failed: cadastros_contadoaplicativo.app_id

The above exception was the direct cause of the following exception:

Traceback (most recent call last):
  File "/mnt/c/Users/jreii/Desktop/IPTVGestão/cadastros/views.py", line 595, in ImportarClientes
    dados_do_app.save()
  File "/mnt/c/Users/jreii/Desktop/IPTVGestão/cadastros/models.py", line 252, in save
    super(ContaDoAplicativo, self).save(*args, **kwargs)
  File "/mnt/c/Users/jreii/Desktop/IPTVGestão/.venv/lib/python3.10/site-packages/django/db/models/base.py", line 814, in save
    self.save_base(
  File "/mnt/c/Users/jreii/Desktop/IPTVGestão/.venv/lib/python3.10/site-packages/django/db/models/base.py", line 877, in save_base
    updated = self._save_table(
  File "/mnt/c/Users/jreii/Desktop/IPTVGestão/.venv/lib/python3.10/site-packages/django/db/models/base.py", line 1020, in _save_table
    results = self._do_insert(
  File "/mnt/c/Users/jreii/Desktop/IPTVGestão/.venv/lib/python3.10/site-packages/django/db/models/base.py", line 1061, in _do_insert
    return manager._insert(
  File "/mnt/c/Users/jreii/Desktop/IPTVGestão/.venv/lib/python3.10/site-packages/django/db/models/manager.py", line 87, in manager_method
    return getattr(self.get_queryset(), name)(*args, **kwargs)
  File "/mnt/c/Users/jreii/Desktop/IPTVGestão/.venv/lib/python3.10/site-packages/django/db/models/query.py", line 1805, in _insert
    return query.get_compiler(using=using).execute_sql(returning_fields)
  File "/mnt/c/Users/jreii/Desktop/IPTVGestão/.venv/lib/python3.10/site-packages/django/db/models/sql/compiler.py", line 1820, in execute_sql
    cursor.execute(sql, params)
  File "/mnt/c/Users/jreii/Desktop/IPTVGestão/.venv/lib/python3.10/site-packages/django/db/backends/utils.py", line 102, in execute
    return super().execute(sql, params)
  File "/mnt/c/Users/jreii/Desktop/IPTVGestão/.venv/lib/python3.10/site-packages/django/db/backends/utils.py", line 67, in execute
    return self._execute_with_wrappers(
  File "/mnt/c/Users/jreii/Desktop/IPTVGestão/.venv/lib/python3.10/site-packages/django/db/backends/utils.py", line 80, in _execute_with_wrappers
    return executor(sql, params, many, context)
  File "/mnt/c/Users/jreii/Desktop/IPTVGestão/.venv/lib/python3.10/site-packages/django/db/backends/utils.py", line 84, in _execute
    with self.db.wrap_database_errors:
  File "/mnt/c/Users/jreii/Desktop/IPTVGestão/.venv/lib/python3.10/site-packages/django/db/utils.py", line 91, in __exit__
    raise dj_exc_value.with_traceback(traceback) from exc_value
  File "/mnt/c/Users/jreii/Desktop/IPTVGestão/.venv/lib/python3.10/site-packages/django/db/backends/utils.py", line 89, in _execute
    return self.cursor.execute(sql, params)
  File "/mnt/c/Users/jreii/Desktop/IPTVGestão/.venv/lib/python3.10/site-packages/django/db/backends/sqlite3/base.py", line 328, in execute
    return super().execute(query, params)
django.db.utils.IntegrityError: NOT NULL constraint failed: cadastros_contadoaplicativo.app_id
[2023-05-19 14:06:37.298826-03:00][USER][admin] [IP][127.0.0.1] [ERRO][NOT NULL constraint failed: cadastros_contadoaplicativo.app_id]
Traceback (most recent call last):
  File "/mnt/c/Users/jreii/Desktop/IPTVGestão/.venv/lib/python3.10/site-packages/django/db/backends/utils.py", line 89, in _execute
    return self.cursor.execute(sql, params)
  File "/mnt/c/Users/jreii/Desktop/IPTVGestão/.venv/lib/python3.10/site-packages/django/db/backends/sqlite3/base.py", line 328, in execute
    return super().execute(query, params)
sqlite3.IntegrityError: NOT NULL constraint failed: cadastros_contadoaplicativo.app_id

The above exception was the direct cause of the following exception:

Traceback (most recent call last):
  File "/mnt/c/Users/jreii/Desktop/IPTVGestão/cadastros/views.py", line 595, in ImportarClientes
    dados_do_app.save()
  File "/mnt/c/Users/jreii/Desktop/IPTVGestão/cadastros/models.py", line 252, in save
    super(ContaDoAplicativo, self).save(*args, **kwargs)
  File "/mnt/c/Users/jreii/Desktop/IPTVGestão/.venv/lib/python3.10/site-packages/django/db/models/base.py", line 814, in save
    self.save_base(
  File "/mnt/c/Users/jreii/Desktop/IPTVGestão/.venv/lib/python3.10/site-packages/django/db/models/base.py", line 877, in save_base
    updated = self._save_table(
  File "/mnt/c/Users/jreii/Desktop/IPTVGestão/.venv/lib/python3.10/site-packages/django/db/models/base.py", line 1020, in _save_table
    results = self._do_insert(
  File "/mnt/c/Users/jreii/Desktop/IPTVGestão/.venv/lib/python3.10/site-packages/django/db/models/base.py", line 1061, in _do_insert
    return manager._insert(
  File "/mnt/c/Users/jreii/Desktop/IPTVGestão/.venv/lib/python3.10/site-packages/django/db/models/manager.py", line 87, in manager_method
    return getattr(self.get_queryset(), name)(*args, **kwargs)
  File "/mnt/c/Users/jreii/Desktop/IPTVGestão/.venv/lib/python3.10/site-packages/django/db/models/query.py", line 1805, in _insert
    return query.get_compiler(using=using).execute_sql(returning_fields)
  File "/mnt/c/Users/jreii/Desktop/IPTVGestão/.venv/lib/python3.10/site-packages/django/db/models/sql/compiler.py", line 1820, in execute_sql
    cursor.execute(sql, params)
  File "/mnt/c/Users/jreii/Desktop/IPTVGestão/.venv/lib/python3.10/site-packages/django/db/backends/utils.py", line 102, in execute
    return super().execute(sql, params)
  File "/mnt/c/Users/jreii/Desktop/IPTVGestão/.venv/lib/python3.10/site-packages/django/db/backends/utils.py", line 67, in execute
    return self._execute_with_wrappers(
  File "/mnt/c/Users/jreii/Desktop/IPTVGestão/.venv/lib/python3.10/site-packages/django/db/backends/utils.py", line 80, in _execute_with_wrappers
    return executor(sql, params, many, context)
  File "/mnt/c/Users/jreii/Desktop/IPTVGestão/.venv/lib/python3.10/site-packages/django/db/backends/utils.py", line 84, in _execute
    with self.db.wrap_database_errors:
  File "/mnt/c/Users/jreii/Desktop/IPTVGestão/.venv/lib/python3.10/site-packages/django/db/utils.py", line 91, in __exit__
    raise dj_exc_value.with_traceback(traceback) from exc_value
  File "/mnt/c/Users/jreii/Desktop/IPTVGestão/.venv/lib/python3.10/site-packages/django/db/backends/utils.py", line 89, in _execute
    return self.cursor.execute(sql, params)
  File "/mnt/c/Users/jreii/Desktop/IPTVGestão/.venv/lib/python3.10/site-packages/django/db/backends/sqlite3/base.py", line 328, in execute
    return super().execute(query, params)
django.db.utils.IntegrityError: NOT NULL constraint failed: cadastros_contadoaplicativo.app_id
[2023-05-19 14:06:37.308032-03:00][USER][admin] [IP][127.0.0.1] [ERRO][NOT NULL constraint failed: cadastros_contadoaplicativo.app_id]
Traceback (most recent call last):
  File "/mnt/c/Users/jreii/Desktop/IPTVGestão/.venv/lib/python3.10/site-packages/django/db/backends/utils.py", line 89, in _execute
    return self.cursor.execute(sql, params)
  File "/mnt/c/Users/jreii/Desktop/IPTVGestão/.venv/lib/python3.10/site-packages/django/db/backends/sqlite3/base.py", line 328, in execute
    return super().execute(query, params)
sqlite3.IntegrityError: NOT NULL constraint failed: cadastros_contadoaplicativo.app_id

The above exception was the direct cause of the following exception:

Traceback (most recent call last):
  File "/mnt/c/Users/jreii/Desktop/IPTVGestão/cadastros/views.py", line 595, in ImportarClientes
    dados_do_app.save()
  File "/mnt/c/Users/jreii/Desktop/IPTVGestão/cadastros/models.py", line 252, in save
    super(ContaDoAplicativo, self).save(*args, **kwargs)
  File "/mnt/c/Users/jreii/Desktop/IPTVGestão/.venv/lib/python3.10/site-packages/django/db/models/base.py", line 814, in save
    self.save_base(
  File "/mnt/c/Users/jreii/Desktop/IPTVGestão/.venv/lib/python3.10/site-packages/django/db/models/base.py", line 877, in save_base
    updated = self._save_table(
  File "/mnt/c/Users/jreii/Desktop/IPTVGestão/.venv/lib/python3.10/site-packages/django/db/models/base.py", line 1020, in _save_table
    results = self._do_insert(
  File "/mnt/c/Users/jreii/Desktop/IPTVGestão/.venv/lib/python3.10/site-packages/django/db/models/base.py", line 1061, in _do_insert
    return manager._insert(
  File "/mnt/c/Users/jreii/Desktop/IPTVGestão/.venv/lib/python3.10/site-packages/django/db/models/manager.py", line 87, in manager_method
    return getattr(self.get_queryset(), name)(*args, **kwargs)
  File "/mnt/c/Users/jreii/Desktop/IPTVGestão/.venv/lib/python3.10/site-packages/django/db/models/query.py", line 1805, in _insert
    return query.get_compiler(using=using).execute_sql(returning_fields)
  File "/mnt/c/Users/jreii/Desktop/IPTVGestão/.venv/lib/python3.10/site-packages/django/db/models/sql/compiler.py", line 1820, in execute_sql
    cursor.execute(sql, params)
  File "/mnt/c/Users/jreii/Desktop/IPTVGestão/.venv/lib/python3.10/site-packages/django/db/backends/utils.py", line 102, in execute
    return super().execute(sql, params)
  File "/mnt/c/Users/jreii/Desktop/IPTVGestão/.venv/lib/python3.10/site-packages/django/db/backends/utils.py", line 67, in execute
    return self._execute_with_wrappers(
  File "/mnt/c/Users/jreii/Desktop/IPTVGestão/.venv/lib/python3.10/site-packages/django/db/backends/utils.py", line 80, in _execute_with_wrappers
    return executor(sql, params, many, context)
  File "/mnt/c/Users/jreii/Desktop/IPTVGestão/.venv/lib/python3.10/site-packages/django/db/backends/utils.py", line 84, in _execute
    with self.db.wrap_database_errors:
  File "/mnt/c/Users/jreii/Desktop/IPTVGestão/.venv/lib/python3.10/site-packages/django/db/utils.py", line 91, in __exit__
    raise dj_exc_value.with_traceback(traceback) from exc_value
  File "/mnt/c/Users/jreii/Desktop/IPTVGestão/.venv/lib/python3.10/site-packages/django/db/backends/utils.py", line 89, in _execute
    return self.cursor.execute(sql, params)
  File "/mnt/c/Users/jreii/Desktop/IPTVGestão/.venv/lib/python3.10/site-packages/django/db/backends/sqlite3/base.py", line 328, in execute
    return super().execute(query, params)
django.db.utils.IntegrityError: NOT NULL constraint failed: cadastros_contadoaplicativo.app_id
[2023-05-19 14:06:37.401557-03:00][USER][admin] [IP][127.0.0.1] [ERRO][NOT NULL constraint failed: cadastros_contadoaplicativo.app_id]
Traceback (most recent call last):
  File "/mnt/c/Users/jreii/Desktop/IPTVGestão/.venv/lib/python3.10/site-packages/django/db/backends/utils.py", line 89, in _execute
    return self.cursor.execute(sql, params)
  File "/mnt/c/Users/jreii/Desktop/IPTVGestão/.venv/lib/python3.10/site-packages/django/db/backends/sqlite3/base.py", line 328, in execute
    return super().execute(query, params)
sqlite3.IntegrityError: NOT NULL constraint failed: cadastros_contadoaplicativo.app_id

The above exception was the direct cause of the following exception:

Traceback (most recent call last):
  File "/mnt/c/Users/jreii/Desktop/IPTVGestão/cadastros/views.py", line 595, in ImportarClientes
    dados_do_app.save()
  File "/mnt/c/Users/jreii/Desktop/IPTVGestão/cadastros/models.py", line 252, in save
    super(ContaDoAplicativo, self).save(*args, **kwargs)
  File "/mnt/c/Users/jreii/Desktop/IPTVGestão/.venv/lib/python3.10/site-packages/django/db/models/base.py", line 814, in save
    self.save_base(
  File "/mnt/c/Users/jreii/Desktop/IPTVGestão/.venv/lib/python3.10/site-packages/django/db/models/base.py", line 877, in save_base
    updated = self._save_table(
  File "/mnt/c/Users/jreii/Desktop/IPTVGestão/.venv/lib/python3.10/site-packages/django/db/models/base.py", line 1020, in _save_table
    results = self._do_insert(
  File "/mnt/c/Users/jreii/Desktop/IPTVGestão/.venv/lib/python3.10/site-packages/django/db/models/base.py", line 1061, in _do_insert
    return manager._insert(
  File "/mnt/c/Users/jreii/Desktop/IPTVGestão/.venv/lib/python3.10/site-packages/django/db/models/manager.py", line 87, in manager_method
    return getattr(self.get_queryset(), name)(*args, **kwargs)
  File "/mnt/c/Users/jreii/Desktop/IPTVGestão/.venv/lib/python3.10/site-packages/django/db/models/query.py", line 1805, in _insert
    return query.get_compiler(using=using).execute_sql(returning_fields)
  File "/mnt/c/Users/jreii/Desktop/IPTVGestão/.venv/lib/python3.10/site-packages/django/db/models/sql/compiler.py", line 1820, in execute_sql
    cursor.execute(sql, params)
  File "/mnt/c/Users/jreii/Desktop/IPTVGestão/.venv/lib/python3.10/site-packages/django/db/backends/utils.py", line 102, in execute
    return super().execute(sql, params)
  File "/mnt/c/Users/jreii/Desktop/IPTVGestão/.venv/lib/python3.10/site-packages/django/db/backends/utils.py", line 67, in execute
    return self._execute_with_wrappers(
  File "/mnt/c/Users/jreii/Desktop/IPTVGestão/.venv/lib/python3.10/site-packages/django/db/backends/utils.py", line 80, in _execute_with_wrappers
    return executor(sql, params, many, context)
  File "/mnt/c/Users/jreii/Desktop/IPTVGestão/.venv/lib/python3.10/site-packages/django/db/backends/utils.py", line 84, in _execute
    with self.db.wrap_database_errors:
  File "/mnt/c/Users/jreii/Desktop/IPTVGestão/.venv/lib/python3.10/site-packages/django/db/utils.py", line 91, in __exit__
    raise dj_exc_value.with_traceback(traceback) from exc_value
  File "/mnt/c/Users/jreii/Desktop/IPTVGestão/.venv/lib/python3.10/site-packages/django/db/backends/utils.py", line 89, in _execute
    return self.cursor.execute(sql, params)
  File "/mnt/c/Users/jreii/Desktop/IPTVGestão/.venv/lib/python3.10/site-packages/django/db/backends/sqlite3/base.py", line 328, in execute
    return super().execute(query, params)
django.db.utils.IntegrityError: NOT NULL constraint failed: cadastros_contadoaplicativo.app_id
[2023-05-19 14:06:37.410539-03:00][USER][admin] [IP][127.0.0.1] [ERRO][NOT NULL constraint failed: cadastros_contadoaplicativo.app_id]
Traceback (most recent call last):
  File "/mnt/c/Users/jreii/Desktop/IPTVGestão/.venv/lib/python3.10/site-packages/django/db/backends/utils.py", line 89, in _execute
    return self.cursor.execute(sql, params)
  File "/mnt/c/Users/jreii/Desktop/IPTVGestão/.venv/lib/python3.10/site-packages/django/db/backends/sqlite3/base.py", line 328, in execute
    return super().execute(query, params)
sqlite3.IntegrityError: NOT NULL constraint failed: cadastros_contadoaplicativo.app_id

The above exception was the direct cause of the following exception:

Traceback (most recent call last):
  File "/mnt/c/Users/jreii/Desktop/IPTVGestão/cadastros/views.py", line 595, in ImportarClientes
    dados_do_app.save()
  File "/mnt/c/Users/jreii/Desktop/IPTVGestão/cadastros/models.py", line 252, in save
    super(ContaDoAplicativo, self).save(*args, **kwargs)
  File "/mnt/c/Users/jreii/Desktop/IPTVGestão/.venv/lib/python3.10/site-packages/django/db/models/base.py", line 814, in save
    self.save_base(
  File "/mnt/c/Users/jreii/Desktop/IPTVGestão/.venv/lib/python3.10/site-packages/django/db/models/base.py", line 877, in save_base
    updated = self._save_table(
  File "/mnt/c/Users/jreii/Desktop/IPTVGestão/.venv/lib/python3.10/site-packages/django/db/models/base.py", line 1020, in _save_table
    results = self._do_insert(
  File "/mnt/c/Users/jreii/Desktop/IPTVGestão/.venv/lib/python3.10/site-packages/django/db/models/base.py", line 1061, in _do_insert
    return manager._insert(
  File "/mnt/c/Users/jreii/Desktop/IPTVGestão/.venv/lib/python3.10/site-packages/django/db/models/manager.py", line 87, in manager_method
    return getattr(self.get_queryset(), name)(*args, **kwargs)
  File "/mnt/c/Users/jreii/Desktop/IPTVGestão/.venv/lib/python3.10/site-packages/django/db/models/query.py", line 1805, in _insert
    return query.get_compiler(using=using).execute_sql(returning_fields)
  File "/mnt/c/Users/jreii/Desktop/IPTVGestão/.venv/lib/python3.10/site-packages/django/db/models/sql/compiler.py", line 1820, in execute_sql
    cursor.execute(sql, params)
  File "/mnt/c/Users/jreii/Desktop/IPTVGestão/.venv/lib/python3.10/site-packages/django/db/backends/utils.py", line 102, in execute
    return super().execute(sql, params)
  File "/mnt/c/Users/jreii/Desktop/IPTVGestão/.venv/lib/python3.10/site-packages/django/db/backends/utils.py", line 67, in execute
    return self._execute_with_wrappers(
  File "/mnt/c/Users/jreii/Desktop/IPTVGestão/.venv/lib/python3.10/site-packages/django/db/backends/utils.py", line 80, in _execute_with_wrappers
    return executor(sql, params, many, context)
  File "/mnt/c/Users/jreii/Desktop/IPTVGestão/.venv/lib/python3.10/site-packages/django/db/backends/utils.py", line 84, in _execute
    with self.db.wrap_database_errors:
  File "/mnt/c/Users/jreii/Desktop/IPTVGestão/.venv/lib/python3.10/site-packages/django/db/utils.py", line 91, in __exit__
    raise dj_exc_value.with_traceback(traceback) from exc_value
  File "/mnt/c/Users/jreii/Desktop/IPTVGestão/.venv/lib/python3.10/site-packages/django/db/backends/utils.py", line 89, in _execute
    return self.cursor.execute(sql, params)
  File "/mnt/c/Users/jreii/Desktop/IPTVGestão/.venv/lib/python3.10/site-packages/django/db/backends/sqlite3/base.py", line 328, in execute
    return super().execute(query, params)
django.db.utils.IntegrityError: NOT NULL constraint failed: cadastros_contadoaplicativo.app_id
[2023-05-19 14:06:37.421993-03:00][USER][admin] [IP][127.0.0.1] [ERRO][NOT NULL constraint failed: cadastros_contadoaplicativo.app_id]
Traceback (most recent call last):
  File "/mnt/c/Users/jreii/Desktop/IPTVGestão/.venv/lib/python3.10/site-packages/django/db/backends/utils.py", line 89, in _execute
    return self.cursor.execute(sql, params)
  File "/mnt/c/Users/jreii/Desktop/IPTVGestão/.venv/lib/python3.10/site-packages/django/db/backends/sqlite3/base.py", line 328, in execute
    return super().execute(query, params)
sqlite3.IntegrityError: NOT NULL constraint failed: cadastros_contadoaplicativo.app_id

The above exception was the direct cause of the following exception:

Traceback (most recent call last):
  File "/mnt/c/Users/jreii/Desktop/IPTVGestão/cadastros/views.py", line 595, in ImportarClientes
    dados_do_app.save()
  File "/mnt/c/Users/jreii/Desktop/IPTVGestão/cadastros/models.py", line 252, in save
    super(ContaDoAplicativo, self).save(*args, **kwargs)
  File "/mnt/c/Users/jreii/Desktop/IPTVGestão/.venv/lib/python3.10/site-packages/django/db/models/base.py", line 814, in save
    self.save_base(
  File "/mnt/c/Users/jreii/Desktop/IPTVGestão/.venv/lib/python3.10/site-packages/django/db/models/base.py", line 877, in save_base
    updated = self._save_table(
  File "/mnt/c/Users/jreii/Desktop/IPTVGestão/.venv/lib/python3.10/site-packages/django/db/models/base.py", line 1020, in _save_table
    results = self._do_insert(
  File "/mnt/c/Users/jreii/Desktop/IPTVGestão/.venv/lib/python3.10/site-packages/django/db/models/base.py", line 1061, in _do_insert
    return manager._insert(
  File "/mnt/c/Users/jreii/Desktop/IPTVGestão/.venv/lib/python3.10/site-packages/django/db/models/manager.py", line 87, in manager_method
    return getattr(self.get_queryset(), name)(*args, **kwargs)
  File "/mnt/c/Users/jreii/Desktop/IPTVGestão/.venv/lib/python3.10/site-packages/django/db/models/query.py", line 1805, in _insert
    return query.get_compiler(using=using).execute_sql(returning_fields)
  File "/mnt/c/Users/jreii/Desktop/IPTVGestão/.venv/lib/python3.10/site-packages/django/db/models/sql/compiler.py", line 1820, in execute_sql
    cursor.execute(sql, params)
  File "/mnt/c/Users/jreii/Desktop/IPTVGestão/.venv/lib/python3.10/site-packages/django/db/backends/utils.py", line 102, in execute
    return super().execute(sql, params)
  File "/mnt/c/Users/jreii/Desktop/IPTVGestão/.venv/lib/python3.10/site-packages/django/db/backends/utils.py", line 67, in execute
    return self._execute_with_wrappers(
  File "/mnt/c/Users/jreii/Desktop/IPTVGestão/.venv/lib/python3.10/site-packages/django/db/backends/utils.py", line 80, in _execute_with_wrappers
    return executor(sql, params, many, context)
  File "/mnt/c/Users/jreii/Desktop/IPTVGestão/.venv/lib/python3.10/site-packages/django/db/backends/utils.py", line 84, in _execute
    with self.db.wrap_database_errors:
  File "/mnt/c/Users/jreii/Desktop/IPTVGestão/.venv/lib/python3.10/site-packages/django/db/utils.py", line 91, in __exit__
    raise dj_exc_value.with_traceback(traceback) from exc_value
  File "/mnt/c/Users/jreii/Desktop/IPTVGestão/.venv/lib/python3.10/site-packages/django/db/backends/utils.py", line 89, in _execute
    return self.cursor.execute(sql, params)
  File "/mnt/c/Users/jreii/Desktop/IPTVGestão/.venv/lib/python3.10/site-packages/django/db/backends/sqlite3/base.py", line 328, in execute
    return super().execute(query, params)
django.db.utils.IntegrityError: NOT NULL constraint failed: cadastros_contadoaplicativo.app_id
Internal Server Error: /admin/cadastros/mensalidade/
Traceback (most recent call last):
  File "/mnt/c/Users/jreii/Desktop/IPTVGestão/.venv/lib/python3.10/site-packages/django/core/handlers/exception.py", line 55, in inner
    response = get_response(request)
  File "/mnt/c/Users/jreii/Desktop/IPTVGestão/.venv/lib/python3.10/site-packages/django/core/handlers/base.py", line 197, in _get_response
    response = wrapped_callback(request, *callback_args, **callback_kwargs)
  File "/mnt/c/Users/jreii/Desktop/IPTVGestão/.venv/lib/python3.10/site-packages/django/contrib/admin/options.py", line 688, in wrapper
    return self.admin_site.admin_view(view)(*args, **kwargs)
  File "/mnt/c/Users/jreii/Desktop/IPTVGestão/.venv/lib/python3.10/site-packages/django/utils/decorators.py", line 134, in _wrapper_view
    response = view_func(request, *args, **kwargs)
  File "/mnt/c/Users/jreii/Desktop/IPTVGestão/.venv/lib/python3.10/site-packages/django/views/decorators/cache.py", line 62, in _wrapper_view_func
    response = view_func(request, *args, **kwargs)
  File "/mnt/c/Users/jreii/Desktop/IPTVGestão/.venv/lib/python3.10/site-packages/django/contrib/admin/sites.py", line 242, in inner
    return view(request, *args, **kwargs)
  File "/mnt/c/Users/jreii/Desktop/IPTVGestão/.venv/lib/python3.10/site-packages/django/utils/decorators.py", line 46, in _wrapper
    return bound_method(*args, **kwargs)
  File "/mnt/c/Users/jreii/Desktop/IPTVGestão/.venv/lib/python3.10/site-packages/django/utils/decorators.py", line 134, in _wrapper_view
    response = view_func(request, *args, **kwargs)
  File "/mnt/c/Users/jreii/Desktop/IPTVGestão/.venv/lib/python3.10/site-packages/django/contrib/admin/options.py", line 1926, in changelist_view
    cl = self.get_changelist_instance(request)
  File "/mnt/c/Users/jreii/Desktop/IPTVGestão/.venv/lib/python3.10/site-packages/django/contrib/admin/options.py", line 836, in get_changelist_instance
    return ChangeList(
  File "/mnt/c/Users/jreii/Desktop/IPTVGestão/.venv/lib/python3.10/site-packages/django/contrib/admin/views/main.py", line 122, in __init__
    self.queryset = self.get_queryset(request)
  File "/mnt/c/Users/jreii/Desktop/IPTVGestão/.venv/lib/python3.10/site-packages/django/contrib/admin/views/main.py", line 529, in get_queryset
    qs, search_may_have_duplicates = self.model_admin.get_search_results(
  File "/mnt/c/Users/jreii/Desktop/IPTVGestão/.venv/lib/python3.10/site-packages/django/contrib/admin/options.py", line 1155, in get_search_results
    queryset = queryset.filter(models.Q.create(term_queries))
  File "/mnt/c/Users/jreii/Desktop/IPTVGestão/.venv/lib/python3.10/site-packages/django/db/models/query.py", line 1436, in filter
    return self._filter_or_exclude(False, args, kwargs)
  File "/mnt/c/Users/jreii/Desktop/IPTVGestão/.venv/lib/python3.10/site-packages/django/db/models/query.py", line 1454, in _filter_or_exclude
    clone._filter_or_exclude_inplace(negate, args, kwargs)
  File "/mnt/c/Users/jreii/Desktop/IPTVGestão/.venv/lib/python3.10/site-packages/django/db/models/query.py", line 1461, in _filter_or_exclude_inplace
    self._query.add_q(Q(*args, **kwargs))
  File "/mnt/c/Users/jreii/Desktop/IPTVGestão/.venv/lib/python3.10/site-packages/django/db/models/sql/query.py", line 1502, in add_q
    clause, _ = self._add_q(q_object, self.used_aliases)
  File "/mnt/c/Users/jreii/Desktop/IPTVGestão/.venv/lib/python3.10/site-packages/django/db/models/sql/query.py", line 1533, in _add_q
    child_clause, needed_inner = self.build_filter(
  File "/mnt/c/Users/jreii/Desktop/IPTVGestão/.venv/lib/python3.10/site-packages/django/db/models/sql/query.py", line 1361, in build_filter
    return self._add_q(
  File "/mnt/c/Users/jreii/Desktop/IPTVGestão/.venv/lib/python3.10/site-packages/django/db/models/sql/query.py", line 1533, in _add_q
    child_clause, needed_inner = self.build_filter(
  File "/mnt/c/Users/jreii/Desktop/IPTVGestão/.venv/lib/python3.10/site-packages/django/db/models/sql/query.py", line 1361, in build_filter
    return self._add_q(
  File "/mnt/c/Users/jreii/Desktop/IPTVGestão/.venv/lib/python3.10/site-packages/django/db/models/sql/query.py", line 1533, in _add_q
    child_clause, needed_inner = self.build_filter(
  File "/mnt/c/Users/jreii/Desktop/IPTVGestão/.venv/lib/python3.10/site-packages/django/db/models/sql/query.py", line 1448, in build_filter
    condition = self.build_lookup(lookups, col, value)
  File "/mnt/c/Users/jreii/Desktop/IPTVGestão/.venv/lib/python3.10/site-packages/django/db/models/sql/query.py", line 1269, in build_lookup
    lhs = self.try_transform(lhs, lookup_name)
  File "/mnt/c/Users/jreii/Desktop/IPTVGestão/.venv/lib/python3.10/site-packages/django/db/models/sql/query.py", line 1313, in try_transform
    raise FieldError(
django.core.exceptions.FieldError: Unsupported lookup 'icontains' for ForeignKey or join on the field not permitted.
Internal Server Error: /admin/cadastros/mensalidade/
Traceback (most recent call last):
  File "/mnt/c/Users/jreii/Desktop/IPTVGestão/.venv/lib/python3.10/site-packages/django/core/handlers/exception.py", line 55, in inner
    response = get_response(request)
  File "/mnt/c/Users/jreii/Desktop/IPTVGestão/.venv/lib/python3.10/site-packages/django/core/handlers/base.py", line 197, in _get_response
    response = wrapped_callback(request, *callback_args, **callback_kwargs)
  File "/mnt/c/Users/jreii/Desktop/IPTVGestão/.venv/lib/python3.10/site-packages/django/contrib/admin/options.py", line 688, in wrapper
    return self.admin_site.admin_view(view)(*args, **kwargs)
  File "/mnt/c/Users/jreii/Desktop/IPTVGestão/.venv/lib/python3.10/site-packages/django/utils/decorators.py", line 134, in _wrapper_view
    response = view_func(request, *args, **kwargs)
  File "/mnt/c/Users/jreii/Desktop/IPTVGestão/.venv/lib/python3.10/site-packages/django/views/decorators/cache.py", line 62, in _wrapper_view_func
    response = view_func(request, *args, **kwargs)
  File "/mnt/c/Users/jreii/Desktop/IPTVGestão/.venv/lib/python3.10/site-packages/django/contrib/admin/sites.py", line 242, in inner
    return view(request, *args, **kwargs)
  File "/mnt/c/Users/jreii/Desktop/IPTVGestão/.venv/lib/python3.10/site-packages/django/utils/decorators.py", line 46, in _wrapper
    return bound_method(*args, **kwargs)
  File "/mnt/c/Users/jreii/Desktop/IPTVGestão/.venv/lib/python3.10/site-packages/django/utils/decorators.py", line 134, in _wrapper_view
    response = view_func(request, *args, **kwargs)
  File "/mnt/c/Users/jreii/Desktop/IPTVGestão/.venv/lib/python3.10/site-packages/django/contrib/admin/options.py", line 1926, in changelist_view
    cl = self.get_changelist_instance(request)
  File "/mnt/c/Users/jreii/Desktop/IPTVGestão/.venv/lib/python3.10/site-packages/django/contrib/admin/options.py", line 836, in get_changelist_instance
    return ChangeList(
  File "/mnt/c/Users/jreii/Desktop/IPTVGestão/.venv/lib/python3.10/site-packages/django/contrib/admin/views/main.py", line 122, in __init__
    self.queryset = self.get_queryset(request)
  File "/mnt/c/Users/jreii/Desktop/IPTVGestão/.venv/lib/python3.10/site-packages/django/contrib/admin/views/main.py", line 529, in get_queryset
    qs, search_may_have_duplicates = self.model_admin.get_search_results(
  File "/mnt/c/Users/jreii/Desktop/IPTVGestão/.venv/lib/python3.10/site-packages/django/contrib/admin/options.py", line 1155, in get_search_results
    queryset = queryset.filter(models.Q.create(term_queries))
  File "/mnt/c/Users/jreii/Desktop/IPTVGestão/.venv/lib/python3.10/site-packages/django/db/models/query.py", line 1436, in filter
    return self._filter_or_exclude(False, args, kwargs)
  File "/mnt/c/Users/jreii/Desktop/IPTVGestão/.venv/lib/python3.10/site-packages/django/db/models/query.py", line 1454, in _filter_or_exclude
    clone._filter_or_exclude_inplace(negate, args, kwargs)
  File "/mnt/c/Users/jreii/Desktop/IPTVGestão/.venv/lib/python3.10/site-packages/django/db/models/query.py", line 1461, in _filter_or_exclude_inplace
    self._query.add_q(Q(*args, **kwargs))
  File "/mnt/c/Users/jreii/Desktop/IPTVGestão/.venv/lib/python3.10/site-packages/django/db/models/sql/query.py", line 1502, in add_q
    clause, _ = self._add_q(q_object, self.used_aliases)
  File "/mnt/c/Users/jreii/Desktop/IPTVGestão/.venv/lib/python3.10/site-packages/django/db/models/sql/query.py", line 1533, in _add_q
    child_clause, needed_inner = self.build_filter(
  File "/mnt/c/Users/jreii/Desktop/IPTVGestão/.venv/lib/python3.10/site-packages/django/db/models/sql/query.py", line 1361, in build_filter
    return self._add_q(
  File "/mnt/c/Users/jreii/Desktop/IPTVGestão/.venv/lib/python3.10/site-packages/django/db/models/sql/query.py", line 1533, in _add_q
    child_clause, needed_inner = self.build_filter(
  File "/mnt/c/Users/jreii/Desktop/IPTVGestão/.venv/lib/python3.10/site-packages/django/db/models/sql/query.py", line 1361, in build_filter
    return self._add_q(
  File "/mnt/c/Users/jreii/Desktop/IPTVGestão/.venv/lib/python3.10/site-packages/django/db/models/sql/query.py", line 1533, in _add_q
    child_clause, needed_inner = self.build_filter(
  File "/mnt/c/Users/jreii/Desktop/IPTVGestão/.venv/lib/python3.10/site-packages/django/db/models/sql/query.py", line 1448, in build_filter
    condition = self.build_lookup(lookups, col, value)
  File "/mnt/c/Users/jreii/Desktop/IPTVGestão/.venv/lib/python3.10/site-packages/django/db/models/sql/query.py", line 1269, in build_lookup
    lhs = self.try_transform(lhs, lookup_name)
  File "/mnt/c/Users/jreii/Desktop/IPTVGestão/.venv/lib/python3.10/site-packages/django/db/models/sql/query.py", line 1313, in try_transform
    raise FieldError(
django.core.exceptions.FieldError: Unsupported lookup 'icontains' for ForeignKey or join on the field not permitted.
"GET /admin/cadastros/mensalidade/?q=welling HTTP/1.1" 500 191255
"GET /admin/cadastros/mensalidade/?q=welling HTTP/1.1" 500 191255
Internal Server Error: /admin/cadastros/mensalidade/
Traceback (most recent call last):
  File "/mnt/c/Users/jreii/Desktop/IPTVGestão/.venv/lib/python3.10/site-packages/django/core/handlers/exception.py", line 55, in inner
    response = get_response(request)
  File "/mnt/c/Users/jreii/Desktop/IPTVGestão/.venv/lib/python3.10/site-packages/django/core/handlers/base.py", line 197, in _get_response
    response = wrapped_callback(request, *callback_args, **callback_kwargs)
  File "/mnt/c/Users/jreii/Desktop/IPTVGestão/.venv/lib/python3.10/site-packages/django/contrib/admin/options.py", line 688, in wrapper
    return self.admin_site.admin_view(view)(*args, **kwargs)
  File "/mnt/c/Users/jreii/Desktop/IPTVGestão/.venv/lib/python3.10/site-packages/django/utils/decorators.py", line 134, in _wrapper_view
    response = view_func(request, *args, **kwargs)
  File "/mnt/c/Users/jreii/Desktop/IPTVGestão/.venv/lib/python3.10/site-packages/django/views/decorators/cache.py", line 62, in _wrapper_view_func
    response = view_func(request, *args, **kwargs)
  File "/mnt/c/Users/jreii/Desktop/IPTVGestão/.venv/lib/python3.10/site-packages/django/contrib/admin/sites.py", line 242, in inner
    return view(request, *args, **kwargs)
  File "/mnt/c/Users/jreii/Desktop/IPTVGestão/.venv/lib/python3.10/site-packages/django/utils/decorators.py", line 46, in _wrapper
    return bound_method(*args, **kwargs)
  File "/mnt/c/Users/jreii/Desktop/IPTVGestão/.venv/lib/python3.10/site-packages/django/utils/decorators.py", line 134, in _wrapper_view
    response = view_func(request, *args, **kwargs)
  File "/mnt/c/Users/jreii/Desktop/IPTVGestão/.venv/lib/python3.10/site-packages/django/contrib/admin/options.py", line 1926, in changelist_view
    cl = self.get_changelist_instance(request)
  File "/mnt/c/Users/jreii/Desktop/IPTVGestão/.venv/lib/python3.10/site-packages/django/contrib/admin/options.py", line 836, in get_changelist_instance
    return ChangeList(
  File "/mnt/c/Users/jreii/Desktop/IPTVGestão/.venv/lib/python3.10/site-packages/django/contrib/admin/views/main.py", line 122, in __init__
    self.queryset = self.get_queryset(request)
  File "/mnt/c/Users/jreii/Desktop/IPTVGestão/.venv/lib/python3.10/site-packages/django/contrib/admin/views/main.py", line 529, in get_queryset
    qs, search_may_have_duplicates = self.model_admin.get_search_results(
  File "/mnt/c/Users/jreii/Desktop/IPTVGestão/.venv/lib/python3.10/site-packages/django/contrib/admin/options.py", line 1155, in get_search_results
    queryset = queryset.filter(models.Q.create(term_queries))
  File "/mnt/c/Users/jreii/Desktop/IPTVGestão/.venv/lib/python3.10/site-packages/django/db/models/query.py", line 1436, in filter
    return self._filter_or_exclude(False, args, kwargs)
  File "/mnt/c/Users/jreii/Desktop/IPTVGestão/.venv/lib/python3.10/site-packages/django/db/models/query.py", line 1454, in _filter_or_exclude
    clone._filter_or_exclude_inplace(negate, args, kwargs)
  File "/mnt/c/Users/jreii/Desktop/IPTVGestão/.venv/lib/python3.10/site-packages/django/db/models/query.py", line 1461, in _filter_or_exclude_inplace
    self._query.add_q(Q(*args, **kwargs))
  File "/mnt/c/Users/jreii/Desktop/IPTVGestão/.venv/lib/python3.10/site-packages/django/db/models/sql/query.py", line 1502, in add_q
    clause, _ = self._add_q(q_object, self.used_aliases)
  File "/mnt/c/Users/jreii/Desktop/IPTVGestão/.venv/lib/python3.10/site-packages/django/db/models/sql/query.py", line 1533, in _add_q
    child_clause, needed_inner = self.build_filter(
  File "/mnt/c/Users/jreii/Desktop/IPTVGestão/.venv/lib/python3.10/site-packages/django/db/models/sql/query.py", line 1361, in build_filter
    return self._add_q(
  File "/mnt/c/Users/jreii/Desktop/IPTVGestão/.venv/lib/python3.10/site-packages/django/db/models/sql/query.py", line 1533, in _add_q
    child_clause, needed_inner = self.build_filter(
  File "/mnt/c/Users/jreii/Desktop/IPTVGestão/.venv/lib/python3.10/site-packages/django/db/models/sql/query.py", line 1361, in build_filter
    return self._add_q(
  File "/mnt/c/Users/jreii/Desktop/IPTVGestão/.venv/lib/python3.10/site-packages/django/db/models/sql/query.py", line 1533, in _add_q
    child_clause, needed_inner = self.build_filter(
  File "/mnt/c/Users/jreii/Desktop/IPTVGestão/.venv/lib/python3.10/site-packages/django/db/models/sql/query.py", line 1448, in build_filter
    condition = self.build_lookup(lookups, col, value)
  File "/mnt/c/Users/jreii/Desktop/IPTVGestão/.venv/lib/python3.10/site-packages/django/db/models/sql/query.py", line 1269, in build_lookup
    lhs = self.try_transform(lhs, lookup_name)
  File "/mnt/c/Users/jreii/Desktop/IPTVGestão/.venv/lib/python3.10/site-packages/django/db/models/sql/query.py", line 1313, in try_transform
    raise FieldError(
django.core.exceptions.FieldError: Unsupported lookup 'icontains' for ForeignKey or join on the field not permitted.
Internal Server Error: /admin/cadastros/mensalidade/
Traceback (most recent call last):
  File "/mnt/c/Users/jreii/Desktop/IPTVGestão/.venv/lib/python3.10/site-packages/django/core/handlers/exception.py", line 55, in inner
    response = get_response(request)
  File "/mnt/c/Users/jreii/Desktop/IPTVGestão/.venv/lib/python3.10/site-packages/django/core/handlers/base.py", line 197, in _get_response
    response = wrapped_callback(request, *callback_args, **callback_kwargs)
  File "/mnt/c/Users/jreii/Desktop/IPTVGestão/.venv/lib/python3.10/site-packages/django/contrib/admin/options.py", line 688, in wrapper
    return self.admin_site.admin_view(view)(*args, **kwargs)
  File "/mnt/c/Users/jreii/Desktop/IPTVGestão/.venv/lib/python3.10/site-packages/django/utils/decorators.py", line 134, in _wrapper_view
    response = view_func(request, *args, **kwargs)
  File "/mnt/c/Users/jreii/Desktop/IPTVGestão/.venv/lib/python3.10/site-packages/django/views/decorators/cache.py", line 62, in _wrapper_view_func
    response = view_func(request, *args, **kwargs)
  File "/mnt/c/Users/jreii/Desktop/IPTVGestão/.venv/lib/python3.10/site-packages/django/contrib/admin/sites.py", line 242, in inner
    return view(request, *args, **kwargs)
  File "/mnt/c/Users/jreii/Desktop/IPTVGestão/.venv/lib/python3.10/site-packages/django/utils/decorators.py", line 46, in _wrapper
    return bound_method(*args, **kwargs)
  File "/mnt/c/Users/jreii/Desktop/IPTVGestão/.venv/lib/python3.10/site-packages/django/utils/decorators.py", line 134, in _wrapper_view
    response = view_func(request, *args, **kwargs)
  File "/mnt/c/Users/jreii/Desktop/IPTVGestão/.venv/lib/python3.10/site-packages/django/contrib/admin/options.py", line 1926, in changelist_view
    cl = self.get_changelist_instance(request)
  File "/mnt/c/Users/jreii/Desktop/IPTVGestão/.venv/lib/python3.10/site-packages/django/contrib/admin/options.py", line 836, in get_changelist_instance
    return ChangeList(
  File "/mnt/c/Users/jreii/Desktop/IPTVGestão/.venv/lib/python3.10/site-packages/django/contrib/admin/views/main.py", line 122, in __init__
    self.queryset = self.get_queryset(request)
  File "/mnt/c/Users/jreii/Desktop/IPTVGestão/.venv/lib/python3.10/site-packages/django/contrib/admin/views/main.py", line 529, in get_queryset
    qs, search_may_have_duplicates = self.model_admin.get_search_results(
  File "/mnt/c/Users/jreii/Desktop/IPTVGestão/.venv/lib/python3.10/site-packages/django/contrib/admin/options.py", line 1155, in get_search_results
    queryset = queryset.filter(models.Q.create(term_queries))
  File "/mnt/c/Users/jreii/Desktop/IPTVGestão/.venv/lib/python3.10/site-packages/django/db/models/query.py", line 1436, in filter
    return self._filter_or_exclude(False, args, kwargs)
  File "/mnt/c/Users/jreii/Desktop/IPTVGestão/.venv/lib/python3.10/site-packages/django/db/models/query.py", line 1454, in _filter_or_exclude
    clone._filter_or_exclude_inplace(negate, args, kwargs)
  File "/mnt/c/Users/jreii/Desktop/IPTVGestão/.venv/lib/python3.10/site-packages/django/db/models/query.py", line 1461, in _filter_or_exclude_inplace
    self._query.add_q(Q(*args, **kwargs))
  File "/mnt/c/Users/jreii/Desktop/IPTVGestão/.venv/lib/python3.10/site-packages/django/db/models/sql/query.py", line 1502, in add_q
    clause, _ = self._add_q(q_object, self.used_aliases)
  File "/mnt/c/Users/jreii/Desktop/IPTVGestão/.venv/lib/python3.10/site-packages/django/db/models/sql/query.py", line 1533, in _add_q
    child_clause, needed_inner = self.build_filter(
  File "/mnt/c/Users/jreii/Desktop/IPTVGestão/.venv/lib/python3.10/site-packages/django/db/models/sql/query.py", line 1361, in build_filter
    return self._add_q(
  File "/mnt/c/Users/jreii/Desktop/IPTVGestão/.venv/lib/python3.10/site-packages/django/db/models/sql/query.py", line 1533, in _add_q
    child_clause, needed_inner = self.build_filter(
  File "/mnt/c/Users/jreii/Desktop/IPTVGestão/.venv/lib/python3.10/site-packages/django/db/models/sql/query.py", line 1361, in build_filter
    return self._add_q(
  File "/mnt/c/Users/jreii/Desktop/IPTVGestão/.venv/lib/python3.10/site-packages/django/db/models/sql/query.py", line 1533, in _add_q
    child_clause, needed_inner = self.build_filter(
  File "/mnt/c/Users/jreii/Desktop/IPTVGestão/.venv/lib/python3.10/site-packages/django/db/models/sql/query.py", line 1448, in build_filter
    condition = self.build_lookup(lookups, col, value)
  File "/mnt/c/Users/jreii/Desktop/IPTVGestão/.venv/lib/python3.10/site-packages/django/db/models/sql/query.py", line 1269, in build_lookup
    lhs = self.try_transform(lhs, lookup_name)
  File "/mnt/c/Users/jreii/Desktop/IPTVGestão/.venv/lib/python3.10/site-packages/django/db/models/sql/query.py", line 1313, in try_transform
    raise FieldError(
django.core.exceptions.FieldError: Unsupported lookup 'icontains' for ForeignKey or join on the field not permitted.
"GET /admin/cadastros/mensalidade/?q=welling HTTP/1.1" 500 191255
"GET /admin/cadastros/mensalidade/?q=welling HTTP/1.1" 500 191255
Internal Server Error: /admin/cadastros/mensalidade/
Traceback (most recent call last):
  File "/mnt/c/Users/jreii/Desktop/IPTVGestão/.venv/lib/python3.10/site-packages/django/core/handlers/exception.py", line 55, in inner
    response = get_response(request)
  File "/mnt/c/Users/jreii/Desktop/IPTVGestão/.venv/lib/python3.10/site-packages/django/core/handlers/base.py", line 197, in _get_response
    response = wrapped_callback(request, *callback_args, **callback_kwargs)
  File "/mnt/c/Users/jreii/Desktop/IPTVGestão/.venv/lib/python3.10/site-packages/django/contrib/admin/options.py", line 688, in wrapper
    return self.admin_site.admin_view(view)(*args, **kwargs)
  File "/mnt/c/Users/jreii/Desktop/IPTVGestão/.venv/lib/python3.10/site-packages/django/utils/decorators.py", line 134, in _wrapper_view
    response = view_func(request, *args, **kwargs)
  File "/mnt/c/Users/jreii/Desktop/IPTVGestão/.venv/lib/python3.10/site-packages/django/views/decorators/cache.py", line 62, in _wrapper_view_func
    response = view_func(request, *args, **kwargs)
  File "/mnt/c/Users/jreii/Desktop/IPTVGestão/.venv/lib/python3.10/site-packages/django/contrib/admin/sites.py", line 242, in inner
    return view(request, *args, **kwargs)
  File "/mnt/c/Users/jreii/Desktop/IPTVGestão/.venv/lib/python3.10/site-packages/django/utils/decorators.py", line 46, in _wrapper
    return bound_method(*args, **kwargs)
  File "/mnt/c/Users/jreii/Desktop/IPTVGestão/.venv/lib/python3.10/site-packages/django/utils/decorators.py", line 134, in _wrapper_view
    response = view_func(request, *args, **kwargs)
  File "/mnt/c/Users/jreii/Desktop/IPTVGestão/.venv/lib/python3.10/site-packages/django/contrib/admin/options.py", line 1926, in changelist_view
    cl = self.get_changelist_instance(request)
  File "/mnt/c/Users/jreii/Desktop/IPTVGestão/.venv/lib/python3.10/site-packages/django/contrib/admin/options.py", line 836, in get_changelist_instance
    return ChangeList(
  File "/mnt/c/Users/jreii/Desktop/IPTVGestão/.venv/lib/python3.10/site-packages/django/contrib/admin/views/main.py", line 122, in __init__
    self.queryset = self.get_queryset(request)
  File "/mnt/c/Users/jreii/Desktop/IPTVGestão/.venv/lib/python3.10/site-packages/django/contrib/admin/views/main.py", line 529, in get_queryset
    qs, search_may_have_duplicates = self.model_admin.get_search_results(
  File "/mnt/c/Users/jreii/Desktop/IPTVGestão/.venv/lib/python3.10/site-packages/django/contrib/admin/options.py", line 1155, in get_search_results
    queryset = queryset.filter(models.Q.create(term_queries))
  File "/mnt/c/Users/jreii/Desktop/IPTVGestão/.venv/lib/python3.10/site-packages/django/db/models/query.py", line 1436, in filter
    return self._filter_or_exclude(False, args, kwargs)
  File "/mnt/c/Users/jreii/Desktop/IPTVGestão/.venv/lib/python3.10/site-packages/django/db/models/query.py", line 1454, in _filter_or_exclude
    clone._filter_or_exclude_inplace(negate, args, kwargs)
  File "/mnt/c/Users/jreii/Desktop/IPTVGestão/.venv/lib/python3.10/site-packages/django/db/models/query.py", line 1461, in _filter_or_exclude_inplace
    self._query.add_q(Q(*args, **kwargs))
  File "/mnt/c/Users/jreii/Desktop/IPTVGestão/.venv/lib/python3.10/site-packages/django/db/models/sql/query.py", line 1502, in add_q
    clause, _ = self._add_q(q_object, self.used_aliases)
  File "/mnt/c/Users/jreii/Desktop/IPTVGestão/.venv/lib/python3.10/site-packages/django/db/models/sql/query.py", line 1533, in _add_q
    child_clause, needed_inner = self.build_filter(
  File "/mnt/c/Users/jreii/Desktop/IPTVGestão/.venv/lib/python3.10/site-packages/django/db/models/sql/query.py", line 1361, in build_filter
    return self._add_q(
  File "/mnt/c/Users/jreii/Desktop/IPTVGestão/.venv/lib/python3.10/site-packages/django/db/models/sql/query.py", line 1533, in _add_q
    child_clause, needed_inner = self.build_filter(
  File "/mnt/c/Users/jreii/Desktop/IPTVGestão/.venv/lib/python3.10/site-packages/django/db/models/sql/query.py", line 1361, in build_filter
    return self._add_q(
  File "/mnt/c/Users/jreii/Desktop/IPTVGestão/.venv/lib/python3.10/site-packages/django/db/models/sql/query.py", line 1533, in _add_q
    child_clause, needed_inner = self.build_filter(
  File "/mnt/c/Users/jreii/Desktop/IPTVGestão/.venv/lib/python3.10/site-packages/django/db/models/sql/query.py", line 1448, in build_filter
    condition = self.build_lookup(lookups, col, value)
  File "/mnt/c/Users/jreii/Desktop/IPTVGestão/.venv/lib/python3.10/site-packages/django/db/models/sql/query.py", line 1269, in build_lookup
    lhs = self.try_transform(lhs, lookup_name)
  File "/mnt/c/Users/jreii/Desktop/IPTVGestão/.venv/lib/python3.10/site-packages/django/db/models/sql/query.py", line 1313, in try_transform
    raise FieldError(
django.core.exceptions.FieldError: Unsupported lookup 'icontains' for ForeignKey or join on the field not permitted.
Internal Server Error: /admin/cadastros/mensalidade/
Traceback (most recent call last):
  File "/mnt/c/Users/jreii/Desktop/IPTVGestão/.venv/lib/python3.10/site-packages/django/core/handlers/exception.py", line 55, in inner
    response = get_response(request)
  File "/mnt/c/Users/jreii/Desktop/IPTVGestão/.venv/lib/python3.10/site-packages/django/core/handlers/base.py", line 197, in _get_response
    response = wrapped_callback(request, *callback_args, **callback_kwargs)
  File "/mnt/c/Users/jreii/Desktop/IPTVGestão/.venv/lib/python3.10/site-packages/django/contrib/admin/options.py", line 688, in wrapper
    return self.admin_site.admin_view(view)(*args, **kwargs)
  File "/mnt/c/Users/jreii/Desktop/IPTVGestão/.venv/lib/python3.10/site-packages/django/utils/decorators.py", line 134, in _wrapper_view
    response = view_func(request, *args, **kwargs)
  File "/mnt/c/Users/jreii/Desktop/IPTVGestão/.venv/lib/python3.10/site-packages/django/views/decorators/cache.py", line 62, in _wrapper_view_func
    response = view_func(request, *args, **kwargs)
  File "/mnt/c/Users/jreii/Desktop/IPTVGestão/.venv/lib/python3.10/site-packages/django/contrib/admin/sites.py", line 242, in inner
    return view(request, *args, **kwargs)
  File "/mnt/c/Users/jreii/Desktop/IPTVGestão/.venv/lib/python3.10/site-packages/django/utils/decorators.py", line 46, in _wrapper
    return bound_method(*args, **kwargs)
  File "/mnt/c/Users/jreii/Desktop/IPTVGestão/.venv/lib/python3.10/site-packages/django/utils/decorators.py", line 134, in _wrapper_view
    response = view_func(request, *args, **kwargs)
  File "/mnt/c/Users/jreii/Desktop/IPTVGestão/.venv/lib/python3.10/site-packages/django/contrib/admin/options.py", line 1926, in changelist_view
    cl = self.get_changelist_instance(request)
  File "/mnt/c/Users/jreii/Desktop/IPTVGestão/.venv/lib/python3.10/site-packages/django/contrib/admin/options.py", line 836, in get_changelist_instance
    return ChangeList(
  File "/mnt/c/Users/jreii/Desktop/IPTVGestão/.venv/lib/python3.10/site-packages/django/contrib/admin/views/main.py", line 122, in __init__
    self.queryset = self.get_queryset(request)
  File "/mnt/c/Users/jreii/Desktop/IPTVGestão/.venv/lib/python3.10/site-packages/django/contrib/admin/views/main.py", line 529, in get_queryset
    qs, search_may_have_duplicates = self.model_admin.get_search_results(
  File "/mnt/c/Users/jreii/Desktop/IPTVGestão/.venv/lib/python3.10/site-packages/django/contrib/admin/options.py", line 1155, in get_search_results
    queryset = queryset.filter(models.Q.create(term_queries))
  File "/mnt/c/Users/jreii/Desktop/IPTVGestão/.venv/lib/python3.10/site-packages/django/db/models/query.py", line 1436, in filter
    return self._filter_or_exclude(False, args, kwargs)
  File "/mnt/c/Users/jreii/Desktop/IPTVGestão/.venv/lib/python3.10/site-packages/django/db/models/query.py", line 1454, in _filter_or_exclude
    clone._filter_or_exclude_inplace(negate, args, kwargs)
  File "/mnt/c/Users/jreii/Desktop/IPTVGestão/.venv/lib/python3.10/site-packages/django/db/models/query.py", line 1461, in _filter_or_exclude_inplace
    self._query.add_q(Q(*args, **kwargs))
  File "/mnt/c/Users/jreii/Desktop/IPTVGestão/.venv/lib/python3.10/site-packages/django/db/models/sql/query.py", line 1502, in add_q
    clause, _ = self._add_q(q_object, self.used_aliases)
  File "/mnt/c/Users/jreii/Desktop/IPTVGestão/.venv/lib/python3.10/site-packages/django/db/models/sql/query.py", line 1533, in _add_q
    child_clause, needed_inner = self.build_filter(
  File "/mnt/c/Users/jreii/Desktop/IPTVGestão/.venv/lib/python3.10/site-packages/django/db/models/sql/query.py", line 1361, in build_filter
    return self._add_q(
  File "/mnt/c/Users/jreii/Desktop/IPTVGestão/.venv/lib/python3.10/site-packages/django/db/models/sql/query.py", line 1533, in _add_q
    child_clause, needed_inner = self.build_filter(
  File "/mnt/c/Users/jreii/Desktop/IPTVGestão/.venv/lib/python3.10/site-packages/django/db/models/sql/query.py", line 1361, in build_filter
    return self._add_q(
  File "/mnt/c/Users/jreii/Desktop/IPTVGestão/.venv/lib/python3.10/site-packages/django/db/models/sql/query.py", line 1533, in _add_q
    child_clause, needed_inner = self.build_filter(
  File "/mnt/c/Users/jreii/Desktop/IPTVGestão/.venv/lib/python3.10/site-packages/django/db/models/sql/query.py", line 1448, in build_filter
    condition = self.build_lookup(lookups, col, value)
  File "/mnt/c/Users/jreii/Desktop/IPTVGestão/.venv/lib/python3.10/site-packages/django/db/models/sql/query.py", line 1269, in build_lookup
    lhs = self.try_transform(lhs, lookup_name)
  File "/mnt/c/Users/jreii/Desktop/IPTVGestão/.venv/lib/python3.10/site-packages/django/db/models/sql/query.py", line 1313, in try_transform
    raise FieldError(
django.core.exceptions.FieldError: Unsupported lookup 'icontains' for ForeignKey or join on the field not permitted.
"GET /admin/cadastros/mensalidade/?q=welling HTTP/1.1" 500 191255
"GET /admin/cadastros/mensalidade/?q=welling HTTP/1.1" 500 191255
Internal Server Error: /admin/cadastros/mensalidade/
Traceback (most recent call last):
  File "/mnt/c/Users/jreii/Desktop/IPTVGestão/.venv/lib/python3.10/site-packages/django/core/handlers/exception.py", line 55, in inner
    response = get_response(request)
  File "/mnt/c/Users/jreii/Desktop/IPTVGestão/.venv/lib/python3.10/site-packages/django/core/handlers/base.py", line 197, in _get_response
    response = wrapped_callback(request, *callback_args, **callback_kwargs)
  File "/mnt/c/Users/jreii/Desktop/IPTVGestão/.venv/lib/python3.10/site-packages/django/contrib/admin/options.py", line 688, in wrapper
    return self.admin_site.admin_view(view)(*args, **kwargs)
  File "/mnt/c/Users/jreii/Desktop/IPTVGestão/.venv/lib/python3.10/site-packages/django/utils/decorators.py", line 134, in _wrapper_view
    response = view_func(request, *args, **kwargs)
  File "/mnt/c/Users/jreii/Desktop/IPTVGestão/.venv/lib/python3.10/site-packages/django/views/decorators/cache.py", line 62, in _wrapper_view_func
    response = view_func(request, *args, **kwargs)
  File "/mnt/c/Users/jreii/Desktop/IPTVGestão/.venv/lib/python3.10/site-packages/django/contrib/admin/sites.py", line 242, in inner
    return view(request, *args, **kwargs)
  File "/mnt/c/Users/jreii/Desktop/IPTVGestão/.venv/lib/python3.10/site-packages/django/utils/decorators.py", line 46, in _wrapper
    return bound_method(*args, **kwargs)
  File "/mnt/c/Users/jreii/Desktop/IPTVGestão/.venv/lib/python3.10/site-packages/django/utils/decorators.py", line 134, in _wrapper_view
    response = view_func(request, *args, **kwargs)
  File "/mnt/c/Users/jreii/Desktop/IPTVGestão/.venv/lib/python3.10/site-packages/django/contrib/admin/options.py", line 1926, in changelist_view
    cl = self.get_changelist_instance(request)
  File "/mnt/c/Users/jreii/Desktop/IPTVGestão/.venv/lib/python3.10/site-packages/django/contrib/admin/options.py", line 836, in get_changelist_instance
    return ChangeList(
  File "/mnt/c/Users/jreii/Desktop/IPTVGestão/.venv/lib/python3.10/site-packages/django/contrib/admin/views/main.py", line 122, in __init__
    self.queryset = self.get_queryset(request)
  File "/mnt/c/Users/jreii/Desktop/IPTVGestão/.venv/lib/python3.10/site-packages/django/contrib/admin/views/main.py", line 529, in get_queryset
    qs, search_may_have_duplicates = self.model_admin.get_search_results(
  File "/mnt/c/Users/jreii/Desktop/IPTVGestão/.venv/lib/python3.10/site-packages/django/contrib/admin/options.py", line 1155, in get_search_results
    queryset = queryset.filter(models.Q.create(term_queries))
  File "/mnt/c/Users/jreii/Desktop/IPTVGestão/.venv/lib/python3.10/site-packages/django/db/models/query.py", line 1436, in filter
    return self._filter_or_exclude(False, args, kwargs)
  File "/mnt/c/Users/jreii/Desktop/IPTVGestão/.venv/lib/python3.10/site-packages/django/db/models/query.py", line 1454, in _filter_or_exclude
    clone._filter_or_exclude_inplace(negate, args, kwargs)
  File "/mnt/c/Users/jreii/Desktop/IPTVGestão/.venv/lib/python3.10/site-packages/django/db/models/query.py", line 1461, in _filter_or_exclude_inplace
    self._query.add_q(Q(*args, **kwargs))
  File "/mnt/c/Users/jreii/Desktop/IPTVGestão/.venv/lib/python3.10/site-packages/django/db/models/sql/query.py", line 1502, in add_q
    clause, _ = self._add_q(q_object, self.used_aliases)
  File "/mnt/c/Users/jreii/Desktop/IPTVGestão/.venv/lib/python3.10/site-packages/django/db/models/sql/query.py", line 1533, in _add_q
    child_clause, needed_inner = self.build_filter(
  File "/mnt/c/Users/jreii/Desktop/IPTVGestão/.venv/lib/python3.10/site-packages/django/db/models/sql/query.py", line 1361, in build_filter
    return self._add_q(
  File "/mnt/c/Users/jreii/Desktop/IPTVGestão/.venv/lib/python3.10/site-packages/django/db/models/sql/query.py", line 1533, in _add_q
    child_clause, needed_inner = self.build_filter(
  File "/mnt/c/Users/jreii/Desktop/IPTVGestão/.venv/lib/python3.10/site-packages/django/db/models/sql/query.py", line 1361, in build_filter
    return self._add_q(
  File "/mnt/c/Users/jreii/Desktop/IPTVGestão/.venv/lib/python3.10/site-packages/django/db/models/sql/query.py", line 1533, in _add_q
    child_clause, needed_inner = self.build_filter(
  File "/mnt/c/Users/jreii/Desktop/IPTVGestão/.venv/lib/python3.10/site-packages/django/db/models/sql/query.py", line 1448, in build_filter
    condition = self.build_lookup(lookups, col, value)
  File "/mnt/c/Users/jreii/Desktop/IPTVGestão/.venv/lib/python3.10/site-packages/django/db/models/sql/query.py", line 1269, in build_lookup
    lhs = self.try_transform(lhs, lookup_name)
  File "/mnt/c/Users/jreii/Desktop/IPTVGestão/.venv/lib/python3.10/site-packages/django/db/models/sql/query.py", line 1313, in try_transform
    raise FieldError(
django.core.exceptions.FieldError: Unsupported lookup 'icontains' for ForeignKey or join on the field not permitted.
Internal Server Error: /admin/cadastros/mensalidade/
Traceback (most recent call last):
  File "/mnt/c/Users/jreii/Desktop/IPTVGestão/.venv/lib/python3.10/site-packages/django/core/handlers/exception.py", line 55, in inner
    response = get_response(request)
  File "/mnt/c/Users/jreii/Desktop/IPTVGestão/.venv/lib/python3.10/site-packages/django/core/handlers/base.py", line 197, in _get_response
    response = wrapped_callback(request, *callback_args, **callback_kwargs)
  File "/mnt/c/Users/jreii/Desktop/IPTVGestão/.venv/lib/python3.10/site-packages/django/contrib/admin/options.py", line 688, in wrapper
    return self.admin_site.admin_view(view)(*args, **kwargs)
  File "/mnt/c/Users/jreii/Desktop/IPTVGestão/.venv/lib/python3.10/site-packages/django/utils/decorators.py", line 134, in _wrapper_view
    response = view_func(request, *args, **kwargs)
  File "/mnt/c/Users/jreii/Desktop/IPTVGestão/.venv/lib/python3.10/site-packages/django/views/decorators/cache.py", line 62, in _wrapper_view_func
    response = view_func(request, *args, **kwargs)
  File "/mnt/c/Users/jreii/Desktop/IPTVGestão/.venv/lib/python3.10/site-packages/django/contrib/admin/sites.py", line 242, in inner
    return view(request, *args, **kwargs)
  File "/mnt/c/Users/jreii/Desktop/IPTVGestão/.venv/lib/python3.10/site-packages/django/utils/decorators.py", line 46, in _wrapper
    return bound_method(*args, **kwargs)
  File "/mnt/c/Users/jreii/Desktop/IPTVGestão/.venv/lib/python3.10/site-packages/django/utils/decorators.py", line 134, in _wrapper_view
    response = view_func(request, *args, **kwargs)
  File "/mnt/c/Users/jreii/Desktop/IPTVGestão/.venv/lib/python3.10/site-packages/django/contrib/admin/options.py", line 1926, in changelist_view
    cl = self.get_changelist_instance(request)
  File "/mnt/c/Users/jreii/Desktop/IPTVGestão/.venv/lib/python3.10/site-packages/django/contrib/admin/options.py", line 836, in get_changelist_instance
    return ChangeList(
  File "/mnt/c/Users/jreii/Desktop/IPTVGestão/.venv/lib/python3.10/site-packages/django/contrib/admin/views/main.py", line 122, in __init__
    self.queryset = self.get_queryset(request)
  File "/mnt/c/Users/jreii/Desktop/IPTVGestão/.venv/lib/python3.10/site-packages/django/contrib/admin/views/main.py", line 529, in get_queryset
    qs, search_may_have_duplicates = self.model_admin.get_search_results(
  File "/mnt/c/Users/jreii/Desktop/IPTVGestão/.venv/lib/python3.10/site-packages/django/contrib/admin/options.py", line 1155, in get_search_results
    queryset = queryset.filter(models.Q.create(term_queries))
  File "/mnt/c/Users/jreii/Desktop/IPTVGestão/.venv/lib/python3.10/site-packages/django/db/models/query.py", line 1436, in filter
    return self._filter_or_exclude(False, args, kwargs)
  File "/mnt/c/Users/jreii/Desktop/IPTVGestão/.venv/lib/python3.10/site-packages/django/db/models/query.py", line 1454, in _filter_or_exclude
    clone._filter_or_exclude_inplace(negate, args, kwargs)
  File "/mnt/c/Users/jreii/Desktop/IPTVGestão/.venv/lib/python3.10/site-packages/django/db/models/query.py", line 1461, in _filter_or_exclude_inplace
    self._query.add_q(Q(*args, **kwargs))
  File "/mnt/c/Users/jreii/Desktop/IPTVGestão/.venv/lib/python3.10/site-packages/django/db/models/sql/query.py", line 1502, in add_q
    clause, _ = self._add_q(q_object, self.used_aliases)
  File "/mnt/c/Users/jreii/Desktop/IPTVGestão/.venv/lib/python3.10/site-packages/django/db/models/sql/query.py", line 1533, in _add_q
    child_clause, needed_inner = self.build_filter(
  File "/mnt/c/Users/jreii/Desktop/IPTVGestão/.venv/lib/python3.10/site-packages/django/db/models/sql/query.py", line 1361, in build_filter
    return self._add_q(
  File "/mnt/c/Users/jreii/Desktop/IPTVGestão/.venv/lib/python3.10/site-packages/django/db/models/sql/query.py", line 1533, in _add_q
    child_clause, needed_inner = self.build_filter(
  File "/mnt/c/Users/jreii/Desktop/IPTVGestão/.venv/lib/python3.10/site-packages/django/db/models/sql/query.py", line 1361, in build_filter
    return self._add_q(
  File "/mnt/c/Users/jreii/Desktop/IPTVGestão/.venv/lib/python3.10/site-packages/django/db/models/sql/query.py", line 1533, in _add_q
    child_clause, needed_inner = self.build_filter(
  File "/mnt/c/Users/jreii/Desktop/IPTVGestão/.venv/lib/python3.10/site-packages/django/db/models/sql/query.py", line 1448, in build_filter
    condition = self.build_lookup(lookups, col, value)
  File "/mnt/c/Users/jreii/Desktop/IPTVGestão/.venv/lib/python3.10/site-packages/django/db/models/sql/query.py", line 1269, in build_lookup
    lhs = self.try_transform(lhs, lookup_name)
  File "/mnt/c/Users/jreii/Desktop/IPTVGestão/.venv/lib/python3.10/site-packages/django/db/models/sql/query.py", line 1313, in try_transform
    raise FieldError(
django.core.exceptions.FieldError: Unsupported lookup 'icontains' for ForeignKey or join on the field not permitted.
"GET /admin/cadastros/mensalidade/?q=welling HTTP/1.1" 500 191392
"GET /admin/cadastros/mensalidade/?q=welling HTTP/1.1" 500 191392
Internal Server Error: /admin/cadastros/cliente/
Traceback (most recent call last):
  File "/mnt/c/Users/jreii/Desktop/IPTVGestão/.venv/lib/python3.10/site-packages/django/core/handlers/exception.py", line 55, in inner
    response = get_response(request)
  File "/mnt/c/Users/jreii/Desktop/IPTVGestão/.venv/lib/python3.10/site-packages/django/core/handlers/base.py", line 197, in _get_response
    response = wrapped_callback(request, *callback_args, **callback_kwargs)
  File "/mnt/c/Users/jreii/Desktop/IPTVGestão/.venv/lib/python3.10/site-packages/django/contrib/admin/options.py", line 688, in wrapper
    return self.admin_site.admin_view(view)(*args, **kwargs)
  File "/mnt/c/Users/jreii/Desktop/IPTVGestão/.venv/lib/python3.10/site-packages/django/utils/decorators.py", line 134, in _wrapper_view
    response = view_func(request, *args, **kwargs)
  File "/mnt/c/Users/jreii/Desktop/IPTVGestão/.venv/lib/python3.10/site-packages/django/views/decorators/cache.py", line 62, in _wrapper_view_func
    response = view_func(request, *args, **kwargs)
  File "/mnt/c/Users/jreii/Desktop/IPTVGestão/.venv/lib/python3.10/site-packages/django/contrib/admin/sites.py", line 242, in inner
    return view(request, *args, **kwargs)
  File "/mnt/c/Users/jreii/Desktop/IPTVGestão/.venv/lib/python3.10/site-packages/django/utils/decorators.py", line 46, in _wrapper
    return bound_method(*args, **kwargs)
  File "/mnt/c/Users/jreii/Desktop/IPTVGestão/.venv/lib/python3.10/site-packages/django/utils/decorators.py", line 134, in _wrapper_view
    response = view_func(request, *args, **kwargs)
  File "/mnt/c/Users/jreii/Desktop/IPTVGestão/.venv/lib/python3.10/site-packages/django/contrib/admin/options.py", line 1926, in changelist_view
    cl = self.get_changelist_instance(request)
  File "/mnt/c/Users/jreii/Desktop/IPTVGestão/.venv/lib/python3.10/site-packages/django/contrib/admin/options.py", line 836, in get_changelist_instance
    return ChangeList(
  File "/mnt/c/Users/jreii/Desktop/IPTVGestão/.venv/lib/python3.10/site-packages/django/contrib/admin/views/main.py", line 122, in __init__
    self.queryset = self.get_queryset(request)
  File "/mnt/c/Users/jreii/Desktop/IPTVGestão/.venv/lib/python3.10/site-packages/django/contrib/admin/views/main.py", line 529, in get_queryset
    qs, search_may_have_duplicates = self.model_admin.get_search_results(
  File "/mnt/c/Users/jreii/Desktop/IPTVGestão/.venv/lib/python3.10/site-packages/django/contrib/admin/options.py", line 1155, in get_search_results
    queryset = queryset.filter(models.Q.create(term_queries))
  File "/mnt/c/Users/jreii/Desktop/IPTVGestão/.venv/lib/python3.10/site-packages/django/db/models/query.py", line 1436, in filter
    return self._filter_or_exclude(False, args, kwargs)
  File "/mnt/c/Users/jreii/Desktop/IPTVGestão/.venv/lib/python3.10/site-packages/django/db/models/query.py", line 1454, in _filter_or_exclude
    clone._filter_or_exclude_inplace(negate, args, kwargs)
  File "/mnt/c/Users/jreii/Desktop/IPTVGestão/.venv/lib/python3.10/site-packages/django/db/models/query.py", line 1461, in _filter_or_exclude_inplace
    self._query.add_q(Q(*args, **kwargs))
  File "/mnt/c/Users/jreii/Desktop/IPTVGestão/.venv/lib/python3.10/site-packages/django/db/models/sql/query.py", line 1502, in add_q
    clause, _ = self._add_q(q_object, self.used_aliases)
  File "/mnt/c/Users/jreii/Desktop/IPTVGestão/.venv/lib/python3.10/site-packages/django/db/models/sql/query.py", line 1533, in _add_q
    child_clause, needed_inner = self.build_filter(
  File "/mnt/c/Users/jreii/Desktop/IPTVGestão/.venv/lib/python3.10/site-packages/django/db/models/sql/query.py", line 1361, in build_filter
    return self._add_q(
  File "/mnt/c/Users/jreii/Desktop/IPTVGestão/.venv/lib/python3.10/site-packages/django/db/models/sql/query.py", line 1533, in _add_q
    child_clause, needed_inner = self.build_filter(
  File "/mnt/c/Users/jreii/Desktop/IPTVGestão/.venv/lib/python3.10/site-packages/django/db/models/sql/query.py", line 1361, in build_filter
    return self._add_q(
  File "/mnt/c/Users/jreii/Desktop/IPTVGestão/.venv/lib/python3.10/site-packages/django/db/models/sql/query.py", line 1533, in _add_q
    child_clause, needed_inner = self.build_filter(
  File "/mnt/c/Users/jreii/Desktop/IPTVGestão/.venv/lib/python3.10/site-packages/django/db/models/sql/query.py", line 1448, in build_filter
    condition = self.build_lookup(lookups, col, value)
  File "/mnt/c/Users/jreii/Desktop/IPTVGestão/.venv/lib/python3.10/site-packages/django/db/models/sql/query.py", line 1269, in build_lookup
    lhs = self.try_transform(lhs, lookup_name)
  File "/mnt/c/Users/jreii/Desktop/IPTVGestão/.venv/lib/python3.10/site-packages/django/db/models/sql/query.py", line 1313, in try_transform
    raise FieldError(
django.core.exceptions.FieldError: Unsupported lookup 'icontains' for ForeignKey or join on the field not permitted.
Internal Server Error: /admin/cadastros/cliente/
Traceback (most recent call last):
  File "/mnt/c/Users/jreii/Desktop/IPTVGestão/.venv/lib/python3.10/site-packages/django/core/handlers/exception.py", line 55, in inner
    response = get_response(request)
  File "/mnt/c/Users/jreii/Desktop/IPTVGestão/.venv/lib/python3.10/site-packages/django/core/handlers/base.py", line 197, in _get_response
    response = wrapped_callback(request, *callback_args, **callback_kwargs)
  File "/mnt/c/Users/jreii/Desktop/IPTVGestão/.venv/lib/python3.10/site-packages/django/contrib/admin/options.py", line 688, in wrapper
    return self.admin_site.admin_view(view)(*args, **kwargs)
  File "/mnt/c/Users/jreii/Desktop/IPTVGestão/.venv/lib/python3.10/site-packages/django/utils/decorators.py", line 134, in _wrapper_view
    response = view_func(request, *args, **kwargs)
  File "/mnt/c/Users/jreii/Desktop/IPTVGestão/.venv/lib/python3.10/site-packages/django/views/decorators/cache.py", line 62, in _wrapper_view_func
    response = view_func(request, *args, **kwargs)
  File "/mnt/c/Users/jreii/Desktop/IPTVGestão/.venv/lib/python3.10/site-packages/django/contrib/admin/sites.py", line 242, in inner
    return view(request, *args, **kwargs)
  File "/mnt/c/Users/jreii/Desktop/IPTVGestão/.venv/lib/python3.10/site-packages/django/utils/decorators.py", line 46, in _wrapper
    return bound_method(*args, **kwargs)
  File "/mnt/c/Users/jreii/Desktop/IPTVGestão/.venv/lib/python3.10/site-packages/django/utils/decorators.py", line 134, in _wrapper_view
    response = view_func(request, *args, **kwargs)
  File "/mnt/c/Users/jreii/Desktop/IPTVGestão/.venv/lib/python3.10/site-packages/django/contrib/admin/options.py", line 1926, in changelist_view
    cl = self.get_changelist_instance(request)
  File "/mnt/c/Users/jreii/Desktop/IPTVGestão/.venv/lib/python3.10/site-packages/django/contrib/admin/options.py", line 836, in get_changelist_instance
    return ChangeList(
  File "/mnt/c/Users/jreii/Desktop/IPTVGestão/.venv/lib/python3.10/site-packages/django/contrib/admin/views/main.py", line 122, in __init__
    self.queryset = self.get_queryset(request)
  File "/mnt/c/Users/jreii/Desktop/IPTVGestão/.venv/lib/python3.10/site-packages/django/contrib/admin/views/main.py", line 529, in get_queryset
    qs, search_may_have_duplicates = self.model_admin.get_search_results(
  File "/mnt/c/Users/jreii/Desktop/IPTVGestão/.venv/lib/python3.10/site-packages/django/contrib/admin/options.py", line 1155, in get_search_results
    queryset = queryset.filter(models.Q.create(term_queries))
  File "/mnt/c/Users/jreii/Desktop/IPTVGestão/.venv/lib/python3.10/site-packages/django/db/models/query.py", line 1436, in filter
    return self._filter_or_exclude(False, args, kwargs)
  File "/mnt/c/Users/jreii/Desktop/IPTVGestão/.venv/lib/python3.10/site-packages/django/db/models/query.py", line 1454, in _filter_or_exclude
    clone._filter_or_exclude_inplace(negate, args, kwargs)
  File "/mnt/c/Users/jreii/Desktop/IPTVGestão/.venv/lib/python3.10/site-packages/django/db/models/query.py", line 1461, in _filter_or_exclude_inplace
    self._query.add_q(Q(*args, **kwargs))
  File "/mnt/c/Users/jreii/Desktop/IPTVGestão/.venv/lib/python3.10/site-packages/django/db/models/sql/query.py", line 1502, in add_q
    clause, _ = self._add_q(q_object, self.used_aliases)
  File "/mnt/c/Users/jreii/Desktop/IPTVGestão/.venv/lib/python3.10/site-packages/django/db/models/sql/query.py", line 1533, in _add_q
    child_clause, needed_inner = self.build_filter(
  File "/mnt/c/Users/jreii/Desktop/IPTVGestão/.venv/lib/python3.10/site-packages/django/db/models/sql/query.py", line 1361, in build_filter
    return self._add_q(
  File "/mnt/c/Users/jreii/Desktop/IPTVGestão/.venv/lib/python3.10/site-packages/django/db/models/sql/query.py", line 1533, in _add_q
    child_clause, needed_inner = self.build_filter(
  File "/mnt/c/Users/jreii/Desktop/IPTVGestão/.venv/lib/python3.10/site-packages/django/db/models/sql/query.py", line 1361, in build_filter
    return self._add_q(
  File "/mnt/c/Users/jreii/Desktop/IPTVGestão/.venv/lib/python3.10/site-packages/django/db/models/sql/query.py", line 1533, in _add_q
    child_clause, needed_inner = self.build_filter(
  File "/mnt/c/Users/jreii/Desktop/IPTVGestão/.venv/lib/python3.10/site-packages/django/db/models/sql/query.py", line 1448, in build_filter
    condition = self.build_lookup(lookups, col, value)
  File "/mnt/c/Users/jreii/Desktop/IPTVGestão/.venv/lib/python3.10/site-packages/django/db/models/sql/query.py", line 1269, in build_lookup
    lhs = self.try_transform(lhs, lookup_name)
  File "/mnt/c/Users/jreii/Desktop/IPTVGestão/.venv/lib/python3.10/site-packages/django/db/models/sql/query.py", line 1313, in try_transform
    raise FieldError(
django.core.exceptions.FieldError: Unsupported lookup 'icontains' for ForeignKey or join on the field not permitted.
"GET /admin/cadastros/cliente/?q=andre+m HTTP/1.1" 500 189730
"GET /admin/cadastros/cliente/?q=andre+m HTTP/1.1" 500 189730
