[2023-06-23 20:07:03] [ERROR] log - Internal Server Error: /enviar_mensagem/
Traceback (most recent call last):
  File "/mnt/c/Users/jreii/Desktop/IPTVGestão/.venv/lib/python3.10/site-packages/django/core/handlers/exception.py", line 55, in inner
    response = get_response(request)
  File "/mnt/c/Users/jreii/Desktop/IPTVGestão/.venv/lib/python3.10/site-packages/django/core/handlers/base.py", line 197, in _get_response
    response = wrapped_callback(request, *callback_args, **callback_kwargs)
  File "/mnt/c/Users/jreii/Desktop/IPTVGestão/.venv/lib/python3.10/site-packages/django/contrib/auth/decorators.py", line 23, in _wrapper_view
    return view_func(request, *args, **kwargs)
  File "/mnt/c/Users/jreii/Desktop/IPTVGestão/cadastros/views.py", line 444, in EnviarMensagemWpp
    enviar_mensagem(url, re.sub(r'\s+|\W', '', cliente.telefone))
  File "/mnt/c/Users/jreii/Desktop/IPTVGestão/cadastros/views.py", line 392, in enviar_mensagem
    response = requests.post(url, headers=headers, json=body)
  File "/mnt/c/Users/jreii/Desktop/IPTVGestão/.venv/lib/python3.10/site-packages/requests/api.py", line 115, in post
    return request("post", url, data=data, json=json, **kwargs)
  File "/mnt/c/Users/jreii/Desktop/IPTVGestão/.venv/lib/python3.10/site-packages/requests/api.py", line 59, in request
    return session.request(method=method, url=url, **kwargs)
  File "/mnt/c/Users/jreii/Desktop/IPTVGestão/.venv/lib/python3.10/site-packages/requests/sessions.py", line 575, in request
    prep = self.prepare_request(req)
  File "/mnt/c/Users/jreii/Desktop/IPTVGestão/.venv/lib/python3.10/site-packages/requests/sessions.py", line 486, in prepare_request
    p.prepare(
  File "/mnt/c/Users/jreii/Desktop/IPTVGestão/.venv/lib/python3.10/site-packages/requests/models.py", line 371, in prepare
    self.prepare_body(data, files, json)
  File "/mnt/c/Users/jreii/Desktop/IPTVGestão/.venv/lib/python3.10/site-packages/requests/models.py", line 511, in prepare_body
    body = complexjson.dumps(json, allow_nan=False)
  File "/usr/lib/python3.10/json/__init__.py", line 238, in dumps
    **kw).encode(obj)
  File "/usr/lib/python3.10/json/encoder.py", line 199, in encode
    chunks = self.iterencode(o, _one_shot=True)
  File "/usr/lib/python3.10/json/encoder.py", line 257, in iterencode
    return _iterencode(o, 0)
  File "/usr/lib/python3.10/json/encoder.py", line 179, in default
    raise TypeError(f'Object of type {o.__class__.__name__} '
TypeError: Object of type InMemoryUploadedFile is not JSON serializable
[2023-06-23 20:07:03] [ERROR] basehttp - "POST /enviar_mensagem/ HTTP/1.1" 500 131808
[2023-06-23 20:07:03] [ERROR] basehttp - "POST /enviar_mensagem/ HTTP/1.1" 500 131808
